Workbook

Sheet Fonctionnement
B4: À LIRE avant de s'aventurer dans le Crypto Planner
C6: FONCTIONNEMENT

Sheet Plateforme pour investir
D3: Profite de mes liens d'affiliation pour bénéficier de cadeaux de premières inscriptions
D5: J'utilise ces plateformes car je leur fais confiance, mais n'oublie pas "not your keys, not your coins"
E13: https://account.paymium.com/sign-up?referral=s89f68qqE_dfqyF8aheD
C15: Français
C16: PSAN
C17: Application idéal pour débuter l'investissement en cryptomonnaies
C19: Les frais d'échanges sont parmis les plus bas du marché français
C20: entre 0,4% et 0,6%
C22: Vidéo tuto Paymium | E22: https://youtu.be/IDh-F6HPe6k
C26: Binance | E26: https://accounts.binance.com/fr/register?ref=35924363
C28: N°1 mondiale des exchanges de cryptomonnaies
C29: Trading / Rendement / NFT
C31: Les meilleurs frais d'échanges du marché crypto
C32: Stockage et rendement
C42: YUZU | E42: https://yuzu.green/
E43: Gagne une box surprise grâce à mon code parainnage:
E44: jeremy1659
C45: Français
C46: PSAN
C47: Application idéal pour l'investissement en cryptomonnaies
C48: Contribue à la décarbonation
C49: Stockage et rendement
C50: Vidéo tuto Yuzu | E50: https://youtu.be/Z8gF0C6if1Y
C56: Swissborg | E56: https://join.swissborg.com/fr/r/jeremyB4BB
E57: Gagne un ticket à gratter swissborg grâce à ce lien
C58: suisse
C59: PSAN
C60: Application idéal pour l'investissement en cryptomonnaies
C61: Stockage et rendement
C68: Degiro | E68: https://www.degiro.fr/parrainage/commencez-a-investir?id=29A9E1A2&utm_source=mgm
C71: Application idéal pour l'investissement en bourse

Sheet OBJECTIFS
C3: Mes OBJECTIFS

Sheet EXEMPLE
B3: NOM de l'Actif
B4: BTC
E15: ="Total Achat "&B4&"" -> Total Achat BTC | F15: Total Achats ($) | H15: Résultat Net | J15: =R55-F16 -> 7526.7246 | P15: ="Total Vente "&B4&"" -> Total Vente BTC | Q15: Total Ventes ($)
E16: =SUMIF(H25:H124,"x",F25:F124) -> 0.39403871 | F16: =SUMIF(H25:H124,"x",D25:D124) -> 8333.3333 | O16: =J15 -> 7526.7246 | P16: =Q35 -> 0.17731742 | Q16: =R55 -> 15860.058
H17: ="Balance "&B4&"" -> Balance BTC | J17: =E16-P16 -> 0.21672129
E18: Prix Moyen d'Achat | F18: =F16/E16 -> 21148.515 | P18: Prix Moyen de Vente | Q18: =Q16/P16 -> 89444.444
N20: =J17 -> 0.21672129
A21: ACHATS | L21: VENTES
D24: Montant IN ($) | E24: ="Prix d'achat "&B4&"" -> Prix d'achat BTC | F24: =B4&" acheté " -> BTC acheté | G24: ORDRE posé | H24: ACHAT validé | I24: Date | N24: ="Prix de vente "&B4&"" -> Prix de vente BTC | O24: % Distribution | P24: ="Nbre "&B4&" à vendre" -> Nbre BTC à vendre | Q24: =B4&" vendu " -> BTC vendu | R24: Montant OUT ($) | S24: Résultat Net | T24: ORDRE posé | U24: VENTE Validée | V24: Date
A25: Plan d'Achat | C25: 1 | D25: =IF(C25<=B$27,B$28,"") -> 333.33333 | E25: 22000 | F25: =IF(D25="",0,IF(E25="",0,D25/E25)) -> 0.015151515 | G25: x | H25: x | I25: 44507 | M25: TP1 | N25: 65000 | O25: 0.1 | P25: =O25*E$16 -> 0.039403871 | Q25: =IF(U25="","",P25) -> 0.039403871 | R25: =N25*P25 -> 2561.2516 | S25: =IF(N25="",#N/A,R25-F$16) -> -5772.0817 | T25: x | U25: x | V25: 45778
A26: Capital Dispo | B26: 5000 | C26: 2 | D26: =IF(C26<=B$27,B$28,"") -> 333.33333 | E26: 21000 | F26: =IF(D26="",0,IF(E26="",0,D26/E26)) -> 0.015873016 | G26: x | H26: x | I26: 44508 | M26: TP2 | N26: 85000 | O26: 0.15 | P26: =O26*E$16 -> 0.059105806 | Q26: =IF(U26="","",P26) -> 0.059105806 | R26: =N26*P26 -> 5023.9935 | S26: =IF(N26="",#N/A,S25+R26) -> -748.08824 | T26: x | U26: x | V26: 45779
A27: Fractionnement | B27: 15 | C27: 3 | D27: =IF(C27<=B$27,B$28,"") -> 333.33333 | E27: 20000 | F27: =IF(D27="",0,IF(E27="",0,D27/E27)) -> 0.016666667 | G27: x | H27: x | I27: 44509 | M27: TP3 | N27: 105000 | O27: 0.2 | P27: =O27*E$16 -> 0.078807741 | Q27: =IF(U27="","",P27) -> 0.078807741 | R27: =N27*P27 -> 8274.8128 | S27: =IF(N27="",#N/A,S26+R27) -> 7526.7246 | T27: x | U27: x | V27: 46145
A28: Montant IN | B28: =B26/B27 -> 333.33333 | C28: 4 | D28: =IF(C28<=B$27,B$28,"") -> 333.33333 | E28: 19000 | F28: =IF(D28="",0,IF(E28="",0,D28/E28)) -> 0.01754386 | G28: x | H28: x | I28: 44510 | M28: TP4 | N28: 125000 | O28: 0.25 | P28: =O28*E$16 -> 0.098509677 | Q28: =IF(U28="","",P28) | R28: =N28*P28 -> 12313.71 | S28: =IF(N28="",#N/A,S27+R28) -> 19840.434 | T28: x | V28: 46146
C29: 5 | D29: =IF(C29<=B$27,B$28,"") -> 333.33333 | E29: 18000 | F29: =IF(D29="",0,IF(E29="",0,D29/E29)) -> 0.018518519 | G29: x | H29: x | I29: 44511 | M29: TP5 | N29: 145000 | O29: 0.15 | P29: =O29*E$16 -> 0.059105806 | Q29: =IF(U29="","",P29) | R29: =N29*P29 -> 8570.3419 | S29: =IF(N29="",#N/A,S28+R29) -> 28410.776 | T29: x | V29: 46512
C30: 6 | D30: =IF(C30<=B$27,B$28,"") -> 333.33333 | E30: 17000 | F30: =IF(D30="",0,IF(E30="",0,D30/E30)) -> 0.019607843 | G30: x | H30: x | I30: 44512 | M30: TP6 | N30: 165000 | O30: 0.1 | P30: =O30*E$16 -> 0.039403871 | Q30: =IF(U30="","",P30) | R30: =N30*P30 -> 6501.6387 | S30: =IF(N30="",#N/A,S29+R30) -> 34912.415 | T30: x | V30: 46513
C31: 7 | D31: =IF(C31<=B$27,B$28,"") -> 333.33333 | E31: 16000 | F31: =IF(D31="",0,IF(E31="",0,D31/E31)) -> 0.020833333 | G31: x | H31: x | I31: 44513 | M31: TP7 | N31: 185000 | O31: 0.05 | P31: =O31*E$16 -> 0.019701935 | Q31: =IF(U31="","",P31) | R31: =N31*P31 -> 3644.858 | S31: =IF(N31="",#N/A,S30+R31) -> 38557.273 | T31: x
C32: 8 | D32: =IF(C32<=B$27,B$28,"") -> 333.33333 | E32: 15000 | F32: =IF(D32="",0,IF(E32="",0,D32/E32)) -> 0.022222222 | G32: x | M32: TP8 | P32: =O32*E$16 -> 0 | Q32: =IF(U32="","",P32) | R32: =N32*P32 -> 0 | S32: =IF(N32="",#N/A,S31+R32) -> #N/A
C33: 9 | D33: =IF(C33<=B$27,B$28,"") -> 333.33333 | E33: 14000 | F33: =IF(D33="",0,IF(E33="",0,D33/E33)) -> 0.023809524 | G33: x | M33: TP9 | P33: =O33*E$16 -> 0 | Q33: =IF(U33="","",P33) | R33: =N33*P33 -> 0 | S33: =IF(N33="",#N/A,S32+R33) -> #N/A
C34: 10 | D34: =IF(C34<=B$27,B$28,"") -> 333.33333 | E34: 13000 | F34: =IF(D34="",0,IF(E34="",0,D34/E34)) -> 0.025641026 | G34: x | M34: TP10 | P34: =O34*E$16 -> 0 | Q34: =IF(U34="","",P34) | R34: =N34*P34 -> 0 | S34: =IF(N34="",#N/A,S33+R34) -> #N/A
C35: 11 | D35: =IF(C35<=B$27,B$28,"") -> 333.33333 | E35: 12000 | F35: =IF(D35="",0,IF(E35="",0,D35/E35)) -> 0.027777778 | G35: x | N35: Total % | O35: =SUM(O25:O34) -> 1 | Q35: =SUM(Q25:Q34) -> 0.17731742
C36: 12 | D36: =IF(C36<=B$27,B$28,"") -> 333.33333 | E36: 11000 | F36: =IF(D36="",0,IF(E36="",0,D36/E36)) -> 0.03030303 | G36: x
C37: 13 | D37: =IF(C37<=B$27,B$28,"") -> 333.33333 | E37: 10000 | F37: =IF(D37="",0,IF(E37="",0,D37/E37)) -> 0.033333333 | G37: x
C38: 14 | D38: =IF(C38<=B$27,B$28,"") -> 333.33333 | E38: 9000 | F38: =IF(D38="",0,IF(E38="",0,D38/E38)) -> 0.037037037 | G38: x
C39: 15 | D39: =IF(C39<=B$27,B$28,"") -> 333.33333 | E39: 8000 | F39: =IF(D39="",0,IF(E39="",0,D39/E39)) -> 0.041666667 | G39: x
C40: 16 | D40: =IF(C40<=B$27,B$28,"") | F40: =IF(D40="",0,IF(E40="",0,D40/E40)) -> 0
C41: 17 | D41: =IF(C41<=B$27,B$28,"") | F41: =IF(D41="",0,IF(E41="",0,D41/E41)) -> 0
C42: 18 | D42: =IF(C42<=B$27,B$28,"") | F42: =IF(D42="",0,IF(E42="",0,D42/E42)) -> 0
C43: 19 | D43: =IF(C43<=B$27,B$28,"") | F43: =IF(D43="",0,IF(E43="",0,D43/E43)) -> 0
C44: 20 | D44: =IF(C44<=B$27,B$28,"") | F44: =IF(D44="",0,IF(E44="",0,D44/E44)) -> 0
C45: 21 | D45: =IF(C45<=B$27,B$28,"") | F45: =IF(D45="",0,IF(E45="",0,D45/E45)) -> 0
C46: 22 | D46: =IF(C46<=B$27,B$28,"") | F46: =IF(D46="",0,IF(E46="",0,D46/E46)) -> 0
C47: 23 | D47: =IF(C47<=B$27,B$28,"") | F47: =IF(D47="",0,IF(E47="",0,D47/E47)) -> 0
C48: 24 | D48: =IF(C48<=B$27,B$28,"") | F48: =IF(D48="",0,IF(E48="",0,D48/E48)) -> 0
C49: 25 | D49: =IF(C49<=B$27,B$28,"") | F49: =IF(D49="",0,IF(E49="",0,D49/E49)) -> 0
A50: Achat unique | C50: 1 | D50: 1000 | E50: 35000 | F50: =IF(D50="",0,IF(E50="",0,D50/E50)) -> 0.028571429 | H50: x | I50: 44470
A51: Dollar Cost Average (DCA) | C51: 2 | D51: 1000 | E51: 27000 | F51: =IF(D51="",0,IF(E51="",0,D51/E51)) -> 0.037037037 | H51: x | I51: 44471
A52: Ordre Limite | C52: 3 | D52: 1000 | E52: 24000 | F52: =IF(D52="",0,IF(E52="",0,D52/E52)) -> 0.041666667 | H52: x | I52: 44472
A53: Ordre Market | C53: 4 | D53: 1000 | E53: 20500 | F53: =IF(D53="",0,IF(E53="",0,D53/E53)) -> 0.048780488 | H53: x | I53: 44473
C54: 5 | D54: 1000 | E54: 18456 | F54: =IF(D54="",0,IF(E54="",0,D54/E54)) -> 0.054182922 | H54: x | I54: 44474
C55: 6 | D55: 1000 | E55: 16777 | F55: =IF(D55="",0,IF(E55="",0,D55/E55)) -> 0.059605412 | H55: x | I55: 44475 | N55: TOTAL VENTE théorique | O55: =SUM(R25:R34) -> 46890.606 | P55: =R55/O55 -> 0.33823529 | Q55: TOTAL VENTE Validée | R55: =SUMIF(U25:U34,"x",R25:R34) -> 15860.058
...

Sheet GLOBAL
H2: OBJECTIF (Montant total des ventes) | L2: =M63 -> 0
B3: PLAN GLOBAL | H3: PROFITS RÉALISÉS : | L3: =N63 -> 0
C10: Montant Investi | E10: =J63 -> 0 | Q10: Ventes Réalisées | S10: =L63 -> 0
H12: Actif | I12: Balance | J12: Achats | K12: % Achats | L12: Ventes | M12: Objectif | N12: Résultat net
H13: ='50'!B$4 -> 0 | I13: ='50'!N$20 -> 0 | J13: ='50'!F$16 -> 0 | K13: =IF(J13=0,#N/A,J13/J$63) -> #N/A | L13: ='50'!Q$16 -> 0 | M13: ='50'!O$55 -> 0 | N13: ='50'!O$16 -> 0
H14: ='21'!B$4 -> 0 | I14: ='21'!N$20 -> 0 | J14: ='21'!F$16 -> 0 | K14: =IF(J14=0,#N/A,J14/J$63) -> #N/A | L14: ='21'!Q$16 -> 0 | M14: ='21'!O$55 -> 0 | N14: ='21'!O$16 -> 0
H15: ='1'!B$4 -> 0 | I15: ='1'!N$20 -> 0 | J15: ='1'!F$16 -> 0 | K15: =IF(J15=0,#N/A,J15/J$63) -> #N/A | L15: ='1'!Q$16 -> 0 | M15: ='1'!O$55 -> 0 | N15: ='1'!O$16 -> 0
H16: ='2'!B$4 -> SUI | I16: ='2'!N$20 -> 0 | J16: ='2'!F$16 -> 0 | K16: =IF(J16=0,#N/A,J16/J$63) -> #N/A | L16: ='2'!Q$16 -> 0 | M16: ='2'!O$55 -> 0 | N16: ='2'!O$16 -> 0
H17: ='3'!B$4 -> 0 | I17: ='3'!N$20 -> 0 | J17: ='3'!F$16 -> 0 | K17: =IF(J17=0,#N/A,J17/J$63) -> #N/A | L17: ='3'!Q$16 -> 0 | M17: ='3'!O$55 -> 0 | N17: ='3'!O$16 -> 0
H18: ='4'!B$4 -> 0 | I18: ='4'!N$20 -> 0 | J18: ='4'!F$16 -> 0 | K18: =IF(J18=0,#N/A,J18/J$63) -> #N/A | L18: ='4'!Q$16 -> 0 | M18: ='4'!O$55 -> 0 | N18: ='4'!O$16 -> 0
H19: ='5'!B$4 -> 0 | I19: ='5'!N$20 -> 0 | J19: ='5'!F$16 -> 0 | K19: =IF(J19=0,#N/A,J19/J$63) -> #N/A | L19: ='5'!Q$16 -> 0 | M19: ='5'!O$55 -> 0 | N19: ='5'!O$16 -> 0
H20: ='6'!B$4 -> 0 | I20: ='6'!N$20 -> 0 | J20: ='6'!F$16 -> 0 | K20: =IF(J20=0,#N/A,J20/J$63) -> #N/A | L20: ='6'!Q$16 -> 0 | M20: ='6'!O$55 -> 0 | N20: ='6'!O$16 -> 0
H21: ='7'!B$4 -> 0 | I21: ='7'!N$20 -> 0 | J21: ='7'!F$16 -> 0 | K21: =IF(J21=0,#N/A,J21/J$63) -> #N/A | L21: ='7'!Q$16 -> 0 | M21: ='7'!O$55 -> 0 | N21: ='7'!O$16 -> 0
H22: ='8'!B$4 -> 0 | I22: ='8'!N$20 -> 0 | J22: ='8'!F$16 -> 0 | K22: =IF(J22=0,#N/A,J22/J$63) -> #N/A | L22: ='8'!Q$16 -> 0 | M22: ='8'!O$55 -> 0 | N22: ='8'!O$16 -> 0
H23: ='9'!B$4 -> 0 | I23: ='9'!N$20 -> 0 | J23: ='9'!F$16 -> 0 | K23: =IF(J23=0,#N/A,J23/J$63) -> #N/A | L23: ='9'!Q$16 -> 0 | M23: ='9'!O$55 -> 0 | N23: ='9'!O$16 -> 0
H24: ='10'!B$4 -> 0 | I24: ='10'!N$20 -> 0 | J24: ='10'!F$16 -> 0 | K24: =IF(J24=0,#N/A,J24/J$63) -> #N/A | L24: ='10'!Q$16 -> 0 | M24: ='10'!O$55 -> 0 | N24: ='10'!O$16 -> 0
H25: ='11'!B$4 -> 0 | I25: ='11'!N$20 -> 0 | J25: ='11'!F$16 -> 0 | K25: =IF(J25=0,#N/A,J25/J$63) -> #N/A | L25: ='11'!Q$16 -> 0 | M25: ='11'!O$55 -> 0 | N25: ='11'!O$16 -> 0
H26: ='12'!B$4 -> 0 | I26: ='12'!N$20 -> 0 | J26: ='12'!F$16 -> 0 | K26: =IF(J26=0,#N/A,J26/J$63) -> #N/A | L26: ='12'!Q$16 -> 0 | M26: ='12'!O$55 -> 0 | N26: ='12'!O$16 -> 0
H27: ='13'!B$4 -> 0 | I27: ='13'!N$20 -> 0 | J27: ='13'!F$16 -> 0 | K27: =IF(J27=0,#N/A,J27/J$63) -> #N/A | L27: ='13'!Q$16 -> 0 | M27: ='13'!O$55 -> 0 | N27: ='13'!O$16 -> 0
H28: ='14'!B$4 -> 0 | I28: ='14'!N$20 -> 0 | J28: ='14'!F$16 -> 0 | K28: =IF(J28=0,#N/A,J28/J$63) -> #N/A | L28: ='14'!Q$16 -> 0 | M28: ='14'!O$55 -> 0 | N28: ='14'!O$16 -> 0
H29: ='16'!B$4 -> 0 | I29: ='16'!N$20 -> 0 | J29: ='16'!F$16 -> 0 | K29: =IF(J29=0,#N/A,J29/J$63) -> #N/A | L29: ='16'!Q$16 -> 0 | M29: ='16'!O$55 -> 0 | N29: ='16'!O$16 -> 0
H30: ='15'!B$4 -> 0 | I30: ='15'!N$20 -> 0 | J30: ='15'!F$16 -> 0 | K30: =IF(J30=0,#N/A,J30/J$63) -> #N/A | L30: ='15'!Q$16 -> 0 | M30: ='15'!O$55 -> 0 | N30: ='15'!O$16 -> 0
H31: ='17'!B$4 -> 0 | I31: ='17'!N$20 -> 0 | J31: ='17'!F$16 -> 0 | K31: =IF(J31=0,#N/A,J31/J$63) -> #N/A | L31: ='17'!Q$16 -> 0 | M31: ='17'!O$55 -> 0 | N31: ='17'!O$16 -> 0
H32: ='18'!B$4 -> 0 | I32: ='18'!N$20 -> 0 | J32: ='18'!F$16 -> 0 | K32: =IF(J32=0,#N/A,J32/J$63) -> #N/A | L32: ='18'!Q$16 -> 0 | M32: ='18'!O$55 -> 0 | N32: ='18'!O$16 -> 0
H33: ='19'!B$4 -> 0 | I33: ='19'!N$20 -> 0 | J33: ='19'!F$16 -> 0 | K33: =IF(J33=0,#N/A,J33/J$63) -> #N/A | L33: ='19'!Q$16 -> 0 | M33: ='19'!O$55 -> 0 | N33: ='19'!O$16 -> 0
H34: ='20'!B$4 -> 0 | I34: ='20'!N$20 -> 0 | J34: ='20'!F$16 -> 0 | K34: =IF(J34=0,#N/A,J34/J$63) -> #N/A | L34: ='20'!Q$16 -> 0 | M34: ='20'!O$55 -> 0 | N34: ='20'!O$16 -> 0
H35: ='22'!B$4 -> 0 | I35: ='22'!N$20 -> 0 | J35: ='22'!F$16 -> 0 | K35: =IF(J35=0,#N/A,J35/J$63) -> #N/A | L35: ='22'!Q$16 -> 0 | M35: ='22'!O$55 -> 0 | N35: ='22'!O$16 -> 0
H36: ='23'!B$4 -> 0 | I36: ='23'!N$20 -> 0 | J36: ='23'!F$16 -> 0 | K36: =IF(J36=0,#N/A,J36/J$63) -> #N/A | L36: ='23'!Q$16 -> 0 | M36: ='23'!O$55 -> 0 | N36: ='23'!O$16 -> 0
H37: ='24'!B$4 -> 0 | I37: ='24'!N$20 -> 0 | J37: ='24'!F$16 -> 0 | K37: =IF(J37=0,#N/A,J37/J$63) -> #N/A | L37: ='24'!Q$16 -> 0 | M37: ='24'!O$55 -> 0 | N37: ='24'!O$16 -> 0
H38: ='25'!B$4 -> 0 | I38: ='25'!N$20 -> 0 | J38: ='25'!F$16 -> 0 | K38: =IF(J38=0,#N/A,J38/J$63) -> #N/A | L38: ='25'!Q$16 -> 0 | M38: ='25'!O$55 -> 0 | N38: ='25'!O$16 -> 0
H39: ='26'!B$4 -> 0 | I39: ='26'!N$20 -> 0 | J39: ='26'!F$16 -> 0 | K39: =IF(J39=0,#N/A,J39/J$63) -> #N/A | L39: ='26'!Q$16 -> 0 | M39: ='26'!O$55 -> 0 | N39: ='26'!O$16 -> 0
H40: ='27'!B$4 -> 0 | I40: ='27'!N$20 -> 0 | J40: ='27'!F$16 -> 0 | K40: =IF(J40=0,#N/A,J40/J$63) -> #N/A | L40: ='27'!Q$16 -> 0 | M40: ='27'!O$55 -> 0 | N40: ='27'!O$16 -> 0
H41: ='28'!B$4 -> 0 | I41: ='28'!N$20 -> 0 | J41: ='28'!F$16 -> 0 | K41: =IF(J41=0,#N/A,J41/J$63) -> #N/A | L41: ='28'!Q$16 -> 0 | M41: ='28'!O$55 -> 0 | N41: ='28'!O$16 -> 0
H42: ='29'!B$4 -> 0 | I42: ='29'!N$20 -> 0 | J42: ='29'!F$16 -> 0 | K42: =IF(J42=0,#N/A,J42/J$63) -> #N/A | L42: ='29'!Q$16 -> 0 | M42: ='29'!O$55 -> 0 | N42: ='29'!O$16 -> 0
H43: ='30'!B$4 -> 0 | I43: ='30'!N$20 -> 0 | J43: ='30'!F$16 -> 0 | K43: =IF(J43=0,#N/A,J43/J$63) -> #N/A | L43: ='30'!Q$16 -> 0 | M43: ='30'!O$55 -> 0 | N43: ='30'!O$16 -> 0
H44: ='31'!B$4 -> 0 | I44: ='31'!N$20 -> 0 | J44: ='31'!F$16 -> 0 | K44: =IF(J44=0,#N/A,J44/J$63) -> #N/A | L44: ='31'!Q$16 -> 0 | M44: ='31'!O$55 -> 0 | N44: ='31'!O$16 -> 0
H45: ='32'!B$4 -> 0 | I45: ='32'!N$20 -> 0 | J45: ='32'!F$16 -> 0 | K45: =IF(J45=0,#N/A,J45/J$63) -> #N/A | L45: ='32'!Q$16 -> 0 | M45: ='32'!O$55 -> 0 | N45: ='32'!O$16 -> 0
H46: ='33'!B$4 -> 0 | I46: ='33'!N$20 -> 0 | J46: ='33'!F$16 -> 0 | K46: =IF(J46=0,#N/A,J46/J$63) -> #N/A | L46: ='33'!Q$16 -> 0 | M46: ='33'!O$55 -> 0 | N46: ='33'!O$16 -> 0
H47: ='34'!B$4 -> 0 | I47: ='34'!N$20 -> 0 | J47: ='34'!F$16 -> 0 | K47: =IF(J47=0,#N/A,J47/J$63) -> #N/A | L47: ='34'!Q$16 -> 0 | M47: ='34'!O$55 -> 0 | N47: ='34'!O$16 -> 0
H48: ='35'!B$4 -> 0 | I48: ='35'!N$20 -> 0 | J48: ='35'!F$16 -> 0 | K48: =IF(J48=0,#N/A,J48/J$63) -> #N/A | L48: ='35'!Q$16 -> 0 | M48: ='35'!O$55 -> 0 | N48: ='35'!O$16 -> 0
...

Sheet 1
B3: NOM de l'Actif
E15: ="Total Achat "&B4&"" -> Total Achat | F15: Total Achats ($) | H15: Résultat Net | J15: =R55-F16 -> 0 | P15: ="Total Vente "&B4&"" -> Total Vente | Q15: Total Ventes ($)
E16: =SUMIF(H25:H124,"x",F25:F124) -> 0 | F16: =SUMIF(H25:H124,"x",D25:D124) -> 0 | O16: =J15 -> 0 | P16: =Q35 -> 0 | Q16: =R55 -> 0
H17: ="Balance "&B4&"" -> Balance | J17: =E16-P16 -> 0
E18: Prix Moyen d'Achat | F18: =F16/E16 -> #DIV/0! | P18: Prix Moyen de Vente | Q18: =Q16/P16 -> #DIV/0!
N20: =J17 -> 0
A21: ACHATS | L21: VENTES
D24: Montant IN ($) | E24: ="Prix d'achat "&B4&"" -> Prix d'achat | F24: =B4&" acheté " -> acheté | G24: ORDRE posé | H24: ACHAT validé | I24: Date | N24: ="Prix de vente "&B4&"" -> Prix de vente | O24: % Distribution | P24: ="Nbre "&B4&" à vendre" -> Nbre à vendre | Q24: =B4&" vendu " -> vendu | R24: Montant OUT ($) | S24: Résultat Net | T24: ORDRE posé | U24: VENTE Validée | V24: Date
A25: Plan d'Achat | C25: 1 | D25: =IF(C25<=B$27,B$28,"") -> 50 | F25: =IF(D25="",0,IF(E25="",0,D25/E25)) -> 0 | M25: TP1 | P25: =O25*E$16 -> 0 | Q25: =IF(U25="","",P25) | R25: =N25*P25 -> 0 | S25: =IF(N25="",#N/A,R25-F$16) -> #N/A | T25: x
A26: Capital Dispo | B26: 500 | C26: 2 | D26: =IF(C26<=B$27,B$28,"") -> 50 | F26: =IF(D26="",0,IF(E26="",0,D26/E26)) -> 0 | M26: TP2 | P26: =O26*E$16 -> 0 | Q26: =IF(U26="","",P26) | R26: =N26*P26 -> 0 | S26: =IF(N26="",#N/A,S25+R26) -> #N/A | T26: x
A27: Fractionnement | B27: 10 | C27: 3 | D27: =IF(C27<=B$27,B$28,"") -> 50 | F27: =IF(D27="",0,IF(E27="",0,D27/E27)) -> 0 | M27: TP3 | P27: =O27*E$16 -> 0 | Q27: =IF(U27="","",P27) | R27: =N27*P27 -> 0 | S27: =IF(N27="",#N/A,S26+R27) -> #N/A | T27: x
A28: Montant IN | B28: =B26/B27 -> 50 | C28: 4 | D28: =IF(C28<=B$27,B$28,"") -> 50 | F28: =IF(D28="",0,IF(E28="",0,D28/E28)) -> 0 | M28: TP4 | P28: =O28*E$16 -> 0 | Q28: =IF(U28="","",P28) | R28: =N28*P28 -> 0 | S28: =IF(N28="",#N/A,S27+R28) -> #N/A
C29: 5 | D29: =IF(C29<=B$27,B$28,"") -> 50 | F29: =IF(D29="",0,IF(E29="",0,D29/E29)) -> 0 | M29: TP5 | P29: =O29*E$16 -> 0 | Q29: =IF(U29="","",P29) | R29: =N29*P29 -> 0 | S29: =IF(N29="",#N/A,S28+R29) -> #N/A
C30: 6 | D30: =IF(C30<=B$27,B$28,"") -> 50 | F30: =IF(D30="",0,IF(E30="",0,D30/E30)) -> 0 | M30: TP6 | P30: =O30*E$16 -> 0 | Q30: =IF(U30="","",P30) | R30: =N30*P30 -> 0 | S30: =IF(N30="",#N/A,S29+R30) -> #N/A
C31: 7 | D31: =IF(C31<=B$27,B$28,"") -> 50 | F31: =IF(D31="",0,IF(E31="",0,D31/E31)) -> 0 | M31: TP7 | P31: =O31*E$16 -> 0 | Q31: =IF(U31="","",P31) | R31: =N31*P31 -> 0 | S31: =IF(N31="",#N/A,S30+R31) -> #N/A
C32: 8 | D32: =IF(C32<=B$27,B$28,"") -> 50 | F32: =IF(D32="",0,IF(E32="",0,D32/E32)) -> 0 | M32: TP8 | P32: =O32*E$16 -> 0 | Q32: =IF(U32="","",P32) | R32: =N32*P32 -> 0 | S32: =IF(N32="",#N/A,S31+R32) -> #N/A
C33: 9 | D33: =IF(C33<=B$27,B$28,"") -> 50 | F33: =IF(D33="",0,IF(E33="",0,D33/E33)) -> 0 | M33: TP9 | P33: =O33*E$16 -> 0 | Q33: =IF(U33="","",P33) | R33: =N33*P33 -> 0 | S33: =IF(N33="",#N/A,S32+R33) -> #N/A
C34: 10 | D34: =IF(C34<=B$27,B$28,"") -> 50 | F34: =IF(D34="",0,IF(E34="",0,D34/E34)) -> 0 | M34: TP10 | P34: =O34*E$16 -> 0 | Q34: =IF(U34="","",P34) | R34: =N34*P34 -> 0 | S34: =IF(N34="",#N/A,S33+R34) -> #N/A
C35: 11 | D35: =IF(C35<=B$27,B$28,"") | F35: =IF(D35="",0,IF(E35="",0,D35/E35)) -> 0 | N35: Total % | O35: =SUM(O25:O34) -> 0 | Q35: =SUM(Q25:Q34) -> 0
C36: 12 | D36: =IF(C36<=B$27,B$28,"") | F36: =IF(D36="",0,IF(E36="",0,D36/E36)) -> 0
C37: 13 | D37: =IF(C37<=B$27,B$28,"") | F37: =IF(D37="",0,IF(E37="",0,D37/E37)) -> 0
C38: 14 | D38: =IF(C38<=B$27,B$28,"") | F38: =IF(D38="",0,IF(E38="",0,D38/E38)) -> 0
C39: 15 | D39: =IF(C39<=B$27,B$28,"") | F39: =IF(D39="",0,IF(E39="",0,D39/E39)) -> 0
C40: 16 | D40: =IF(C40<=B$27,B$28,"") | F40: =IF(D40="",0,IF(E40="",0,D40/E40)) -> 0
C41: 17 | D41: =IF(C41<=B$27,B$28,"") | F41: =IF(D41="",0,IF(E41="",0,D41/E41)) -> 0
C42: 18 | D42: =IF(C42<=B$27,B$28,"") | F42: =IF(D42="",0,IF(E42="",0,D42/E42)) -> 0
C43: 19 | D43: =IF(C43<=B$27,B$28,"") | F43: =IF(D43="",0,IF(E43="",0,D43/E43)) -> 0
C44: 20 | D44: =IF(C44<=B$27,B$28,"") | F44: =IF(D44="",0,IF(E44="",0,D44/E44)) -> 0
C45: 21 | D45: =IF(C45<=B$27,B$28,"") | F45: =IF(D45="",0,IF(E45="",0,D45/E45)) -> 0
C46: 22 | D46: =IF(C46<=B$27,B$28,"") | F46: =IF(D46="",0,IF(E46="",0,D46/E46)) -> 0
C47: 23 | D47: =IF(C47<=B$27,B$28,"") | F47: =IF(D47="",0,IF(E47="",0,D47/E47)) -> 0
... C49: 25 | D49: =IF(C49<=B$27,B$28,"") | F49: =IF(D49="",0,IF(E49="",0,D49/E49)) -> 0
A50: Achat unique | C50: 1 | F50: =IF(D50="",0,IF(E50="",0,D50/E50)) -> 0
A51: Dollar Cost Average (DCA) | C51: 2 | F51: =IF(D51="",0,IF(E51="",0,D51/E51)) -> 0
A52: Ordre Limite | C52: 3 | F52: =IF(D52="",0,IF(E52="",0,D52/E52)) -> 0
A53: Ordre Market | C53: 4 | F53: =IF(D53="",0,IF(E53="",0,D53/E53)) -> 0
C54: 5 | F54: =IF(D54="",0,IF(E54="",0,D54/E54)) -> 0
C55: 6 | F55: =IF(D55="",0,IF(E55="",0,D55/E55)) -> 0 | N55: TOTAL VENTE théorique | O55: =SUM(R25:R34) -> 0 | P55: =R55/O55 -> #DIV/0! | Q55: TOTAL VENTE Validée | R55: =SUMIF(U25:U34,"x",R25:R34) -> 0
C56: 7 | F56: =IF(D56="",0,IF(E56="",0,D56/E56)) -> 0
C57: 8 | F57: =IF(D57="",0,IF(E57="",0,D57/E57)) -> 0 | N57: Rendement théorique | O57: =(O55/F16)-1 -> #DIV/0! | Q57: Rendement en cours | R57: =(R55-F16)/F16 -> #DIV/0!
...

Sheet 2
B3: NOM de l'Actif
B4: SUI
E15: ="Total Achat "&B4&"" -> Total Achat SUI | F15: Total Achats ($) | H15: Résultat Net | J15: =R55-F16 -> 0 | P15: ="Total Vente "&B4&"" -> Total Vente SUI | Q15: Total Ventes ($)
E16: =SUMIF(H25:H120,"x",F25:F120) -> 0 | F16: =SUMIF(H25:H120,"x",D25:D120) -> 0 | O16: =J15 -> 0 | P16: =Q35 -> 0 | Q16: =R55 -> 0
H17: ="Balance "&B4&"" -> Balance SUI | J17: =E16-P16 -> 0
E18: Prix Moyen d'Achat | F18: =F16/E16 -> #DIV/0! | P18: Prix Moyen de Vente | Q18: =Q16/P16 -> #DIV/0!
N20: =J17 -> 0
A21: ACHATS | L21: VENTES
D24: Montant IN ($) | E24: ="Prix d'achat "&B4&"" -> Prix d'achat SUI | F24: =B4&" acheté " -> SUI acheté | G24: ORDRE posé | H24: ACHAT validé | I24: Date | N24: ="Prix de vente "&B4&"" -> Prix de vente SUI | O24: % Distribution | P24: ="Nbre "&B4&" à vendre" -> Nbre SUI à vendre | Q24: =B4&" vendu " -> SUI vendu | R24: Montant OUT ($) | S24: Résultat Net | T24: ORDRE posé | U24: VENTE Validée | V24: Date
A25: Plan d'Achat | C25: 1 | D25: =IF(C25<=B$27,B$28,"") -> 50 | F25: =IF(D25="",0,IF(E25="",0,D25/E25)) -> 0 | M25: TP1 | P25: =O25*E$16 -> 0 | Q25: =IF(U25="","",P25) | R25: =N25*P25 -> 0 | S25: =IF(N25="",#N/A,R25-F$16) -> #N/A
A26: Capital Dispo | B26: 500 | C26: 2 | D26: =IF(C26<=B$27,B$28,"") -> 50 | F26: =IF(D26="",0,IF(E26="",0,D26/E26)) -> 0 | M26: TP2 | P26: =O26*E$16 -> 0 | Q26: =IF(U26="","",P26) | R26: =N26*P26 -> 0 | S26: =IF(N26="",#N/A,S25+R26) -> #N/A
A27: Fractionnement | B27: 10 | C27: 3 | D27: =IF(C27<=B$27,B$28,"") -> 50 | F27: =IF(D27="",0,IF(E27="",0,D27/E27)) -> 0 | M27: TP3 | P27: =O27*E$16 -> 0 | Q27: =IF(U27="","",P27) | R27: =N27*P27 -> 0 | S27: =IF(N27="",#N/A,S26+R27) -> #N/A
A28: Montant IN | B28: =B26/B27 -> 50 | C28: 4 | D28: =IF(C28<=B$27,B$28,"") -> 50 | F28: =IF(D28="",0,IF(E28="",0,D28/E28)) -> 0 | M28: TP4 | P28: =O28*E$16 -> 0 | Q28: =IF(U28="","",P28) | R28: =N28*P28 -> 0 | S28: =IF(N28="",#N/A,S27+R28) -> #N/A
C29: 5 | D29: =IF(C29<=B$27,B$28,"") -> 50 | F29: =IF(D29="",0,IF(E29="",0,D29/E29)) -> 0 | M29: TP5 | P29: =O29*E$16 -> 0 | Q29: =IF(U29="","",P29) | R29: =N29*P29 -> 0 | S29: =IF(N29="",#N/A,S28+R29) -> #N/A
C30: 6 | D30: =IF(C30<=B$27,B$28,"") -> 50 | F30: =IF(D30="",0,IF(E30="",0,D30/E30)) -> 0 | M30: TP6 | P30: =O30*E$16 -> 0 | Q30: =IF(U30="","",P30) | R30: =N30*P30 -> 0 | S30: =IF(N30="",#N/A,S29+R30) -> #N/A
C31: 7 | D31: =IF(C31<=B$27,B$28,"") -> 50 | F31: =IF(D31="",0,IF(E31="",0,D31/E31)) -> 0 | M31: TP7 | P31: =O31*E$16 -> 0 | Q31: =IF(U31="","",P31) | R31: =N31*P31 -> 0 | S31: =IF(N31="",#N/A,S30+R31) -> #N/A
C32: 8 | D32: =IF(C32<=B$27,B$28,"") -> 50 | F32: =IF(D32="",0,IF(E32="",0,D32/E32)) -> 0 | M32: TP8 | P32: =O32*E$16 -> 0 | Q32: =IF(U32="","",P32) | R32: =N32*P32 -> 0 | S32: =IF(N32="",#N/A,S31+R32) -> #N/A
C33: 9 | D33: =IF(C33<=B$27,B$28,"") -> 50 | F33: =IF(D33="",0,IF(E33="",0,D33/E33)) -> 0 | M33: TP9 | P33: =O33*E$16 -> 0 | Q33: =IF(U33="","",P33) | R33: =N33*P33 -> 0 | S33: =IF(N33="",#N/A,S32+R33) -> #N/A
C34: 10 | D34: =IF(C34<=B$27,B$28,"") -> 50 | F34: =IF(D34="",0,IF(E34="",0,D34/E34)) -> 0 | M34: TP10 | P34: =O34*E$16 -> 0 | Q34: =IF(U34="","",P34) | R34: =N34*P34 -> 0 | S34: =IF(N34="",#N/A,S33+R34) -> #N/A
C35: 11 | D35: =IF(C35<=B$27,B$28,"") | F35: =IF(D35="",0,IF(E35="",0,D35/E35)) -> 0 | N35: Total % | O35: =SUM(O25:O34) -> 0 | Q35: =SUM(Q25:Q34) -> 0
C36: 12 | D36: =IF(C36<=B$27,B$28,"") | F36: =IF(D36="",0,IF(E36="",0,D36/E36)) -> 0
C37: 13 | D37: =IF(C37<=B$27,B$28,"") | F37: =IF(D37="",0,IF(E37="",0,D37/E37)) -> 0
C38: 14 | D38: =IF(C38<=B$27,B$28,"") | F38: =IF(D38="",0,IF(E38="",0,D38/E38)) -> 0
C39: 15 | D39: =IF(C39<=B$27,B$28,"") | F39: =IF(D39="",0,IF(E39="",0,D39/E39)) -> 0
C40: 16 | D40: =IF(C40<=B$27,B$28,"") | F40: =IF(D40="",0,IF(E40="",0,D40/E40)) -> 0
C41: 17 | D41: =IF(C41<=B$27,B$28,"") | F41: =IF(D41="",0,IF(E41="",0,D41/E41)) -> 0
C42: 18 | D42: =IF(C42<=B$27,B$28,"") | F42: =IF(D42="",0,IF(E42="",0,D42/E42)) -> 0
C43: 19 | D43: =IF(C43<=B$27,B$28,"") | F43: =IF(D43="",0,IF(E43="",0,D43/E43)) -> 0
C44: 20 | D44: =IF(C44<=B$27,B$28,"") | F44: =IF(D44="",0,IF(E44="",0,D44/E44)) -> 0
C45: 21 | D45: =IF(C45<=B$27,B$28,"") | F45: =IF(D45="",0,IF(E45="",0,D45/E45)) -> 0
C46: 22 | D46: =IF(C46<=B$27,B$28,"") | F46: =IF(D46="",0,IF(E46="",0,D46/E46)) -> 0
C47: 23 | D47: =IF(C47<=B$27,B$28,"") | F47: =IF(D47="",0,IF(E47="",0,D47/E47)) -> 0
... C49: 25 | D49: =IF(C49<=B$27,B$28,"") | F49: =IF(D49="",0,IF(E49="",0,D49/E49)) -> 0
A50: Achat unique | C50: 1 | F50: =IF(D50="",0,IF(E50="",0,D50/E50)) -> 0
A51: Dollar Cost Average (DCA) | C51: 2 | F51: =IF(D51="",0,IF(E51="",0,D51/E51)) -> 0
A52: Ordre Limite | C52: 3 | F52: =IF(D52="",0,IF(E52="",0,D52/E52)) -> 0
A53: Ordre Market | C53: 4 | F53: =IF(D53="",0,IF(E53="",0,D53/E53)) -> 0
C54: 5 | F54: =IF(D54="",0,IF(E54="",0,D54/E54)) -> 0
C55: 6 | F55: =IF(D55="",0,IF(E55="",0,D55/E55)) -> 0 | N55: TOTAL VENTE théorique | O55: =SUM(R25:R34) -> 0 | P55: =R55/O55 -> #DIV/0! | Q55: TOTAL VENTE Validée | R55: =SUMIF(U25:U34,"x",R25:R34) -> 0
C56: 7 | F56: =IF(D56="",0,IF(E56="",0,D56/E56)) -> 0
...

Sheet 3
B3: NOM de l'Actif
E15: ="Total Achat "&B4&"" -> Total Achat | F15: Total Achats ($) | H15: Résultat Net | J15: =R55-F16 -> 0 | P15: ="Total Vente "&B4&"" -> Total Vente | Q15: Total Ventes ($)
E16: =SUMIF(H25:H124,"x",F25:F124) -> 0 | F16: =SUMIF(H25:H124,"x",D25:D124) -> 0 | O16: =J15 -> 0 | P16: =Q35 -> 0 | Q16: =R55 -> 0
H17: ="Balance "&B4&"" -> Balance | J17: =E16-P16 -> 0
E18: Prix Moyen d'Achat | F18: =F16/E16 -> #DIV/0! | P18: Prix Moyen de Vente | Q18: =Q16/P16 -> #DIV/0!
N20: =J17 -> 0
A21: ACHATS | L21: VENTES
D24: Montant IN ($) | E24: ="Prix d'achat "&B4&"" -> Prix d'achat | F24: =B4&" acheté " -> acheté | G24: ORDRE posé | H24: ACHAT validé | I24: Date | N24: ="Prix de vente "&B4&"" -> Prix de vente | O24: % Distribution | P24: ="Nbre "&B4&" à vendre" -> Nbre à vendre | Q24: =B4&" vendu " -> vendu | R24: Montant OUT ($) | S24: Résultat Net | T24: ORDRE posé | U24: VENTE Validée | V24: Date
A25: Plan d'Achat | C25: 1 | D25: =IF(C25<=B$27,B$28,"") -> 50 | F25: =IF(D25="",0,IF(E25="",0,D25/E25)) -> 0 | M25: TP1 | P25: =O25*E$16 -> 0 | Q25: =IF(U25="","",P25) | R25: =N25*P25 -> 0 | S25: =IF(N25="",#N/A,R25-F$16) -> #N/A
A26: Capital Dispo | B26: 500 | C26: 2 | D26: =IF(C26<=B$27,B$28,"") -> 50 | F26: =IF(D26="",0,IF(E26="",0,D26/E26)) -> 0 | M26: TP2 | P26: =O26*E$16 -> 0 | Q26: =IF(U26="","",P26) | R26: =N26*P26 -> 0 | S26: =IF(N26="",#N/A,S25+R26) -> #N/A
A27: Fractionnement | B27: 10 | C27: 3 | D27: =IF(C27<=B$27,B$28,"") -> 50 | F27: =IF(D27="",0,IF(E27="",0,D27/E27)) -> 0 | M27: TP3 | P27: =O27*E$16 -> 0 | Q27: =IF(U27="","",P27) | R27: =N27*P27 -> 0 | S27: =IF(N27="",#N/A,S26+R27) -> #N/A
A28: Montant IN | B28: =B26/B27 -> 50 | C28: 4 | D28: =IF(C28<=B$27,B$28,"") -> 50 | F28: =IF(D28="",0,IF(E28="",0,D28/E28)) -> 0 | M28: TP4 | P28: =O28*E$16 -> 0 | Q28: =IF(U28="","",P28) | R28: =N28*P28 -> 0 | S28: =IF(N28="",#N/A,S27+R28) -> #N/A
C29: 5 | D29: =IF(C29<=B$27,B$28,"") -> 50 | F29: =IF(D29="",0,IF(E29="",0,D29/E29)) -> 0 | M29: TP5 | P29: =O29*E$16 -> 0 | Q29: =IF(U29="","",P29) | R29: =N29*P29 -> 0 | S29: =IF(N29="",#N/A,S28+R29) -> #N/A
C30: 6 | D30: =IF(C30<=B$27,B$28,"") -> 50 | F30: =IF(D30="",0,IF(E30="",0,D30/E30)) -> 0 | M30: TP6 | P30: =O30*E$16 -> 0 | Q30: =IF(U30="","",P30) | R30: =N30*P30 -> 0 | S30: =IF(N30="",#N/A,S29+R30) -> #N/A
C31: 7 | D31: =IF(C31<=B$27,B$28,"") -> 50 | F31: =IF(D31="",0,IF(E31="",0,D31/E31)) -> 0 | M31: TP7 | P31: =O31*E$16 -> 0 | Q31: =IF(U31="","",P31) | R31: =N31*P31 -> 0 | S31: =IF(N31="",#N/A,S30+R31) -> #N/A
C32: 8 | D32: =IF(C32<=B$27,B$28,"") -> 50 | F32: =IF(D32="",0,IF(E32="",0,D32/E32)) -> 0 | M32: TP8 | P32: =O32*E$16 -> 0 | Q32: =IF(U32="","",P32) | R32: =N32*P32 -> 0 | S32: =IF(N32="",#N/A,S31+R32) -> #N/A
C33: 9 | D33: =IF(C33<=B$27,B$28,"") -> 50 | F33: =IF(D33="",0,IF(E33="",0,D33/E33)) -> 0 | M33: TP9 | P33: =O33*E$16 -> 0 | Q33: =IF(U33="","",P33) | R33: =N33*P33 -> 0 | S33: =IF(N33="",#N/A,S32+R33) -> #N/A
C34: 10 | D34: =IF(C34<=B$27,B$28,"") -> 50 | F34: =IF(D34="",0,IF(E34="",0,D34/E34)) -> 0 | M34: TP10 | P34: =O34*E$16 -> 0 | Q34: =IF(U34="","",P34) | R34: =N34*P34 -> 0 | S34: =IF(N34="",#N/A,S33+R34) -> #N/A
C35: 11 | D35: =IF(C35<=B$27,B$28,"") | F35: =IF(D35="",0,IF(E35="",0,D35/E35)) -> 0 | N35: Total % | O35: =SUM(O25:O34) -> 0 | Q35: =SUM(Q25:Q34) -> 0
C36: 12 | D36: =IF(C36<=B$27,B$28,"") | F36: =IF(D36="",0,IF(E36="",0,D36/E36)) -> 0
C37: 13 | D37: =IF(C37<=B$27,B$28,"") | F37: =IF(D37="",0,IF(E37="",0,D37/E37)) -> 0
C38: 14 | D38: =IF(C38<=B$27,B$28,"") | F38: =IF(D38="",0,IF(E38="",0,D38/E38)) -> 0
C39: 15 | D39: =IF(C39<=B$27,B$28,"") | F39: =IF(D39="",0,IF(E39="",0,D39/E39)) -> 0
C40: 16 | D40: =IF(C40<=B$27,B$28,"") | F40: =IF(D40="",0,IF(E40="",0,D40/E40)) -> 0
C41: 17 | D41: =IF(C41<=B$27,B$28,"") | F41: =IF(D41="",0,IF(E41="",0,D41/E41)) -> 0
C42: 18 | D42: =IF(C42<=B$27,B$28,"") | F42: =IF(D42="",0,IF(E42="",0,D42/E42)) -> 0
C43: 19 | D43: =IF(C43<=B$27,B$28,"") | F43: =IF(D43="",0,IF(E43="",0,D43/E43)) -> 0
C44: 20 | D44: =IF(C44<=B$27,B$28,"") | F44: =IF(D44="",0,IF(E44="",0,D44/E44)) -> 0
C45: 21 | D45: =IF(C45<=B$27,B$28,"") | F45: =IF(D45="",0,IF(E45="",0,D45/E45)) -> 0
C46: 22 | D46: =IF(C46<=B$27,B$28,"") | F46: =IF(D46="",0,IF(E46="",0,D46/E46)) -> 0
C47: 23 | D47: =IF(C47<=B$27,B$28,"") | F47: =IF(D47="",0,IF(E47="",0,D47/E47)) -> 0
... C49: 25 | D49: =IF(C49<=B$27,B$28,"") | F49: =IF(D49="",0,IF(E49="",0,D49/E49)) -> 0
A50: Achat unique | C50: 1 | F50: =IF(D50="",0,IF(E50="",0,D50/E50)) -> 0
A51: Dollar Cost Average (DCA) | C51: 2 | F51: =IF(D51="",0,IF(E51="",0,D51/E51)) -> 0
A52: Ordre Limite | C52: 3 | F52: =IF(D52="",0,IF(E52="",0,D52/E52)) -> 0
A53: Ordre Market | C53: 4 | F53: =IF(D53="",0,IF(E53="",0,D53/E53)) -> 0
C54: 5 | F54: =IF(D54="",0,IF(E54="",0,D54/E54)) -> 0
C55: 6 | F55: =IF(D55="",0,IF(E55="",0,D55/E55)) -> 0 | N55: TOTAL VENTE théorique | O55: =SUM(R25:R34) -> 0 | P55: =R55/O55 -> #DIV/0! | Q55: TOTAL VENTE Validée | R55: =SUMIF(U25:U34,"x",R25:R34) -> 0
C56: 7 | F56: =IF(D56="",0,IF(E56="",0,D56/E56)) -> 0
C57: 8 | F57: =IF(D57="",0,IF(E57="",0,D57/E57)) -> 0 | N57: Rendement théorique | O57: =(O55/F16)-1 -> #DIV/0! | Q57: Rendement en cours | R57: =(R55-F16)/F16 -> #DIV/0!
...

Sheet 4
B3: NOM de l'Actif
E15: ="Total Achat "&B4&"" -> Total Achat | F15: Total Achats ($) | H15: Résultat Net | J15: =R55-F16 -> 0 | P15: ="Total Vente "&B4&"" -> Total Vente | Q15: Total Ventes ($)
E16: =SUMIF(H25:H124,"x",F25:F124) -> 0 | F16: =SUMIF(H25:H124,"x",D25:D124) -> 0 | O16: =J15 -> 0 | P16: =Q35 -> 0 | Q16: =R55 -> 0
H17: ="Balance "&B4&"" -> Balance | J17: =E16-P16 -> 0
E18: Prix Moyen d'Achat | F18: =F16/E16 -> #DIV/0! | P18: Prix Moyen de Vente | Q18: =Q16/P16 -> #DIV/0!
N20: =J17 -> 0
A21: ACHATS | L21: VENTES
D24: Montant IN ($) | E24: ="Prix d'achat "&B4&"" -> Prix d'achat | F24: =B4&" acheté " -> acheté | G24: ORDRE posé | H24: ACHAT validé | I24: Date | N24: ="Prix de vente "&B4&"" -> Prix de vente | O24: % Distribution | P24: ="Nbre "&B4&" à vendre" -> Nbre à vendre | Q24: =B4&" vendu " -> vendu | R24: Montant OUT ($) | S24: Résultat Net | T24: ORDRE posé | U24: VENTE Validée | V24: Date
A25: Plan d'Achat | C25: 1 | D25: =IF(C25<=B$27,B$28,"") -> 50 | F25: =IF(D25="",0,IF(E25="",0,D25/E25)) -> 0 | M25: TP1 | P25: =O25*E$16 -> 0 | Q25: =IF(U25="","",P25) | R25: =N25*P25 -> 0 | S25: =IF(N25="",#N/A,R25-F$16) -> #N/A
A26: Capital Dispo | B26: 500 | C26: 2 | D26: =IF(C26<=B$27,B$28,"") -> 50 | F26: =IF(D26="",0,IF(E26="",0,D26/E26)) -> 0 | M26: TP2 | P26: =O26*E$16 -> 0 | Q26: =IF(U26="","",P26) | R26: =N26*P26 -> 0 | S26: =IF(N26="",#N/A,S25+R26) -> #N/A
A27: Fractionnement | B27: 10 | C27: 3 | D27: =IF(C27<=B$27,B$28,"") -> 50 | F27: =IF(D27="",0,IF(E27="",0,D27/E27)) -> 0 | M27: TP3 | P27: =O27*E$16 -> 0 | Q27: =IF(U27="","",P27) | R27: =N27*P27 -> 0 | S27: =IF(N27="",#N/A,S26+R27) -> #N/A
A28: Montant IN | B28: =B26/B27 -> 50 | C28: 4 | D28: =IF(C28<=B$27,B$28,"") -> 50 | F28: =IF(D28="",0,IF(E28="",0,D28/E28)) -> 0 | M28: TP4 | P28: =O28*E$16 -> 0 | Q28: =IF(U28="","",P28) | R28: =N28*P28 -> 0 | S28: =IF(N28="",#N/A,S27+R28) -> #N/A
C29: 5 | D29: =IF(C29<=B$27,B$28,"") -> 50 | F29: =IF(D29="",0,IF(E29="",0,D29/E29)) -> 0 | M29: TP5 | P29: =O29*E$16 -> 0 | Q29: =IF(U29="","",P29) | R29: =N29*P29 -> 0 | S29: =IF(N29="",#N/A,S28+R29) -> #N/A
C30: 6 | D30: =IF(C30<=B$27,B$28,"") -> 50 | F30: =IF(D30="",0,IF(E30="",0,D30/E30)) -> 0 | M30: TP6 | P30: =O30*E$16 -> 0 | Q30: =IF(U30="","",P30) | R30: =N30*P30 -> 0 | S30: =IF(N30="",#N/A,S29+R30) -> #N/A
C31: 7 | D31: =IF(C31<=B$27,B$28,"") -> 50 | F31: =IF(D31="",0,IF(E31="",0,D31/E31)) -> 0 | M31: TP7 | P31: =O31*E$16 -> 0 | Q31: =IF(U31="","",P31) | R31: =N31*P31 -> 0 | S31: =IF(N31="",#N/A,S30+R31) -> #N/A
C32: 8 | D32: =IF(C32<=B$27,B$28,"") -> 50 | F32: =IF(D32="",0,IF(E32="",0,D32/E32)) -> 0 | M32: TP8 | P32: =O32*E$16 -> 0 | Q32: =IF(U32="","",P32) | R32: =N32*P32 -> 0 | S32: =IF(N32="",#N/A,S31+R32) -> #N/A
C33: 9 | D33: =IF(C33<=B$27,B$28,"") -> 50 | F33: =IF(D33="",0,IF(E33="",0,D33/E33)) -> 0 | M33: TP9 | P33: =O33*E$16 -> 0 | Q33: =IF(U33="","",P33) | R33: =N33*P33 -> 0 | S33: =IF(N33="",#N/A,S32+R33) -> #N/A
C34: 10 | D34: =IF(C34<=B$27,B$28,"") -> 50 | F34: =IF(D34="",0,IF(E34="",0,D34/E34)) -> 0 | M34: TP10 | P34: =O34*E$16 -> 0 | Q34: =IF(U34="","",P34) | R34: =N34*P34 -> 0 | S34: =IF(N34="",#N/A,S33+R34) -> #N/A
C35: 11 | D35: =IF(C35<=B$27,B$28,"") | F35: =IF(D35="",0,IF(E35="",0,D35/E35)) -> 0 | N35: Total % | O35: =SUM(O25:O34) -> 0 | Q35: =SUM(Q25:Q34) -> 0
C36: 12 | D36: =IF(C36<=B$27,B$28,"") | F36: =IF(D36="",0,IF(E36="",0,D36/E36)) -> 0
C37: 13 | D37: =IF(C37<=B$27,B$28,"") | F37: =IF(D37="",0,IF(E37="",0,D37/E37)) -> 0
C38: 14 | D38: =IF(C38<=B$27,B$28,"") | F38: =IF(D38="",0,IF(E38="",0,D38/E38)) -> 0
C39: 15 | D39: =IF(C39<=B$27,B$28,"") | F39: =IF(D39="",0,IF(E39="",0,D39/E39)) -> 0
C40: 16 | D40: =IF(C40<=B$27,B$28,"") | F40: =IF(D40="",0,IF(E40="",0,D40/E40)) -> 0
C41: 17 | D41: =IF(C41<=B$27,B$28,"") | F41: =IF(D41="",0,IF(E41="",0,D41/E41)) -> 0
C42: 18 | D42: =IF(C42<=B$27,B$28,"") | F42: =IF(D42="",0,IF(E42="",0,D42/E42)) -> 0
C43: 19 | D43: =IF(C43<=B$27,B$28,"") | F43: =IF(D43="",0,IF(E43="",0,D43/E43)) -> 0
C44: 20 | D44: =IF(C44<=B$27,B$28,"") | F44: =IF(D44="",0,IF(E44="",0,D44/E44)) -> 0
C45: 21 | D45: =IF(C45<=B$27,B$28,"") | F45: =IF(D45="",0,IF(E45="",0,D45/E45)) -> 0
C46: 22 | D46: =IF(C46<=B$27,B$28,"") | F46: =IF(D46="",0,IF(E46="",0,D46/E46)) -> 0
C47: 23 | D47: =IF(C47<=B$27,B$28,"") | F47: =IF(D47="",0,IF(E47="",0,D47/E47)) -> 0
... C49: 25 | D49: =IF(C49<=B$27,B$28,"") | F49: =IF(D49="",0,IF(E49="",0,D49/E49)) -> 0
A50: Achat unique | C50: 1 | F50: =IF(D50="",0,IF(E50="",0,D50/E50)) -> 0
A51: Dollar Cost Average (DCA) | C51: 2 | F51: =IF(D51="",0,IF(E51="",0,D51/E51)) -> 0
A52: Ordre Limite | C52: 3 | F52: =IF(D52="",0,IF(E52="",0,D52/E52)) -> 0
A53: Ordre Market | C53: 4 | F53: =IF(D53="",0,IF(E53="",0,D53/E53)) -> 0
C54: 5 | F54: =IF(D54="",0,IF(E54="",0,D54/E54)) -> 0
C55: 6 | F55: =IF(D55="",0,IF(E55="",0,D55/E55)) -> 0 | N55: TOTAL VENTE théorique | O55: =SUM(R25:R34) -> 0 | P55: =R55/O55 -> #DIV/0! | Q55: TOTAL VENTE Validée | R55: =SUMIF(U25:U34,"x",R25:R34) -> 0
C56: 7 | F56: =IF(D56="",0,IF(E56="",0,D56/E56)) -> 0
C57: 8 | F57: =IF(D57="",0,IF(E57="",0,D57/E57)) -> 0 | N57: Rendement théorique | O57: =(O55/F16)-1 -> #DIV/0! | Q57: Rendement en cours | R57: =(R55-F16)/F16 -> #DIV/0!
...

Sheet 5
B3: NOM de l'Actif
E15: ="Total Achat "&B4&"" -> Total Achat | F15: Total Achats ($) | H15: Résultat Net | J15: =R55-F16 -> 0 | P15: ="Total Vente "&B4&"" -> Total Vente | Q15: Total Ventes ($)
E16: =SUMIF(H25:H124,"x",F25:F124) -> 0 | F16: =SUMIF(H25:H124,"x",D25:D124) -> 0 | O16: =J15 -> 0 | P16: =Q35 -> 0 | Q16: =R55 -> 0
H17: ="Balance "&B4&"" -> Balance | J17: =E16-P16 -> 0
E18: Prix Moyen d'Achat | F18: =F16/E16 -> #DIV/0! | P18: Prix Moyen de Vente | Q18: =Q16/P16 -> #DIV/0!
N20: =J17 -> 0
A21: ACHATS | L21: VENTES
D24: Montant IN ($) | E24: ="Prix d'achat "&B4&"" -> Prix d'achat | F24: =B4&" acheté " -> acheté | G24: ORDRE posé | H24: ACHAT validé | I24: Date | N24: ="Prix de vente "&B4&"" -> Prix de vente | O24: % Distribution | P24: ="Nbre "&B4&" à vendre" -> Nbre à vendre | Q24: =B4&" vendu " -> vendu | R24: Montant OUT ($) | S24: Résultat Net | T24: ORDRE posé | U24: VENTE Validée | V24: Date
A25: Plan d'Achat | C25: 1 | D25: =IF(C25<=B$27,B$28,"") -> 50 | F25: =IF(D25="",0,IF(E25="",0,D25/E25)) -> 0 | M25: TP1 | P25: =O25*E$16 -> 0 | Q25: =IF(U25="","",P25) | R25: =N25*P25 -> 0 | S25: =IF(N25="",#N/A,R25-F$16) -> #N/A
A26: Capital Dispo | B26: 500 | C26: 2 | D26: =IF(C26<=B$27,B$28,"") -> 50 | F26: =IF(D26="",0,IF(E26="",0,D26/E26)) -> 0 | M26: TP2 | P26: =O26*E$16 -> 0 | Q26: =IF(U26="","",P26) | R26: =N26*P26 -> 0 | S26: =IF(N26="",#N/A,S25+R26) -> #N/A
A27: Fractionnement | B27: 10 | C27: 3 | D27: =IF(C27<=B$27,B$28,"") -> 50 | F27: =IF(D27="",0,IF(E27="",0,D27/E27)) -> 0 | M27: TP3 | P27: =O27*E$16 -> 0 | Q27: =IF(U27="","",P27) | R27: =N27*P27 -> 0 | S27: =IF(N27="",#N/A,S26+R27) -> #N/A
A28: Montant IN | B28: =B26/B27 -> 50 | C28: 4 | D28: =IF(C28<=B$27,B$28,"") -> 50 | F28: =IF(D28="",0,IF(E28="",0,D28/E28)) -> 0 | M28: TP4 | P28: =O28*E$16 -> 0 | Q28: =IF(U28="","",P28) | R28: =N28*P28 -> 0 | S28: =IF(N28="",#N/A,S27+R28) -> #N/A
C29: 5 | D29: =IF(C29<=B$27,B$28,"") -> 50 | F29: =IF(D29="",0,IF(E29="",0,D29/E29)) -> 0 | M29: TP5 | P29: =O29*E$16 -> 0 | Q29: =IF(U29="","",P29) | R29: =N29*P29 -> 0 | S29: =IF(N29="",#N/A,S28+R29) -> #N/A
C30: 6 | D30: =IF(C30<=B$27,B$28,"") -> 50 | F30: =IF(D30="",0,IF(E30="",0,D30/E30)) -> 0 | M30: TP6 | P30: =O30*E$16 -> 0 | Q30: =IF(U30="","",P30) | R30: =N30*P30 -> 0 | S30: =IF(N30="",#N/A,S29+R30) -> #N/A
C31: 7 | D31: =IF(C31<=B$27,B$28,"") -> 50 | F31: =IF(D31="",0,IF(E31="",0,D31/E31)) -> 0 | M31: TP7 | P31: =O31*E$16 -> 0 | Q31: =IF(U31="","",P31) | R31: =N31*P31 -> 0 | S31: =IF(N31="",#N/A,S30+R31) -> #N/A
C32: 8 | D32: =IF(C32<=B$27,B$28,"") -> 50 | F32: =IF(D32="",0,IF(E32="",0,D32/E32)) -> 0 | M32: TP8 | P32: =O32*E$16 -> 0 | Q32: =IF(U32="","",P32) | R32: =N32*P32 -> 0 | S32: =IF(N32="",#N/A,S31+R32) -> #N/A
C33: 9 | D33: =IF(C33<=B$27,B$28,"") -> 50 | F33: =IF(D33="",0,IF(E33="",0,D33/E33)) -> 0 | M33: TP9 | P33: =O33*E$16 -> 0 | Q33: =IF(U33="","",P33) | R33: =N33*P33 -> 0 | S33: =IF(N33="",#N/A,S32+R33) -> #N/A
C34: 10 | D34: =IF(C34<=B$27,B$28,"") -> 50 | F34: =IF(D34="",0,IF(E34="",0,D34/E34)) -> 0 | M34: TP10 | P34: =O34*E$16 -> 0 | Q34: =IF(U34="","",P34) | R34: =N34*P34 -> 0 | S34: =IF(N34="",#N/A,S33+R34) -> #N/A
C35: 11 | D35: =IF(C35<=B$27,B$28,"") | F35: =IF(D35="",0,IF(E35="",0,D35/E35)) -> 0 | N35: Total % | O35: =SUM(O25:O34) -> 0 | Q35: =SUM(Q25:Q34) -> 0
C36: 12 | D36: =IF(C36<=B$27,B$28,"") | F36: =IF(D36="",0,IF(E36="",0,D36/E36)) -> 0
C37: 13 | D37: =IF(C37<=B$27,B$28,"") | F37: =IF(D37="",0,IF(E37="",0,D37/E37)) -> 0
C38: 14 | D38: =IF(C38<=B$27,B$28,"") | F38: =IF(D38="",0,IF(E38="",0,D38/E38)) -> 0
C39: 15 | D39: =IF(C39<=B$27,B$28,"") | F39: =IF(D39="",0,IF(E39="",0,D39/E39)) -> 0
C40: 16 | D40: =IF(C40<=B$27,B$28,"") | F40: =IF(D40="",0,IF(E40="",0,D40/E40)) -> 0
C41: 17 | D41: =IF(C41<=B$27,B$28,"") | F41: =IF(D41="",0,IF(E41="",0,D41/E41)) -> 0
C42: 18 | D42: =IF(C42<=B$27,B$28,"") | F42: =IF(D42="",0,IF(E42="",0,D42/E42)) -> 0
C43: 19 | D43: =IF(C43<=B$27,B$28,"") | F43: =IF(D43="",0,IF(E43="",0,D43/E43)) -> 0
C44: 20 | D44: =IF(C44<=B$27,B$28,"") | F44: =IF(D44="",0,IF(E44="",0,D44/E44)) -> 0
C45: 21 | D45: =IF(C45<=B$27,B$28,"") | F45: =IF(D45="",0,IF(E45="",0,D45/E45)) -> 0
C46: 22 | D46: =IF(C46<=B$27,B$28,"") | F46: =IF(D46="",0,IF(E46="",0,D46/E46)) -> 0
C47: 23 | D47: =IF(C47<=B$27,B$28,"") | F47: =IF(D47="",0,IF(E47="",0,D47/E47)) -> 0
... C49: 25 | D49: =IF(C49<=B$27,B$28,"") | F49: =IF(D49="",0,IF(E49="",0,D49/E49)) -> 0
A50: Achat unique | C50: 1 | F50: =IF(D50="",0,IF(E50="",0,D50/E50)) -> 0
A51: Dollar Cost Average (DCA) | C51: 2 | F51: =IF(D51="",0,IF(E51="",0,D51/E51)) -> 0
A52: Ordre Limite | C52: 3 | F52: =IF(D52="",0,IF(E52="",0,D52/E52)) -> 0
A53: Ordre Market | C53: 4 | F53: =IF(D53="",0,IF(E53="",0,D53/E53)) -> 0
C54: 5 | F54: =IF(D54="",0,IF(E54="",0,D54/E54)) -> 0
C55: 6 | F55: =IF(D55="",0,IF(E55="",0,D55/E55)) -> 0 | N55: TOTAL VENTE théorique | O55: =SUM(R25:R34) -> 0 | P55: =R55/O55 -> #DIV/0! | Q55: TOTAL VENTE Validée | R55: =SUMIF(U25:U34,"x",R25:R34) -> 0
C56: 7 | F56: =IF(D56="",0,IF(E56="",0,D56/E56)) -> 0
C57: 8 | F57: =IF(D57="",0,IF(E57="",0,D57/E57)) -> 0 | N57: Rendement théorique | O57: =(O55/F16)-1 -> #DIV/0! | Q57: Rendement en cours | R57: =(R55-F16)/F16 -> #DIV/0!
...

Sheet 6
B3: NOM de l'Actif
E15: ="Total Achat "&B4&"" -> Total Achat | F15: Total Achats ($) | H15: Résultat Net | J15: =R55-F16 -> 0 | P15: ="Total Vente "&B4&"" -> Total Vente | Q15: Total Ventes ($)
E16: =SUMIF(H25:H124,"x",F25:F124) -> 0 | F16: =SUMIF(H25:H124,"x",D25:D124) -> 0 | O16: =J15 -> 0 | P16: =Q35 -> 0 | Q16: =R55 -> 0
H17: ="Balance "&B4&"" -> Balance | J17: =E16-P16 -> 0
E18: Prix Moyen d'Achat | F18: =F16/E16 -> #DIV/0! | P18: Prix Moyen de Vente | Q18: =Q16/P16 -> #DIV/0!
N20: =J17 -> 0
A21: ACHATS | L21: VENTES
D24: Montant IN ($) | E24: ="Prix d'achat "&B4&"" -> Prix d'achat | F24: =B4&" acheté " -> acheté | G24: ORDRE posé | H24: ACHAT validé | I24: Date | N24: ="Prix de vente "&B4&"" -> Prix de vente | O24: % Distribution | P24: ="Nbre "&B4&" à vendre" -> Nbre à vendre | Q24: =B4&" vendu " -> vendu | R24: Montant OUT ($) | S24: Résultat Net | T24: ORDRE posé | U24: VENTE Validée | V24: Date
A25: Plan d'Achat | C25: 1 | D25: =IF(C25<=B$27,B$28,"") -> 50 | F25: =IF(D25="",0,IF(E25="",0,D25/E25)) -> 0 | M25: TP1 | P25: =O25*E$16 -> 0 | Q25: =IF(U25="","",P25) | R25: =N25*P25 -> 0 | S25: =IF(N25="",#N/A,R25-F$16) -> #N/A
A26: Capital Dispo | B26: 500 | C26: 2 | D26: =IF(C26<=B$27,B$28,"") -> 50 | F26: =IF(D26="",0,IF(E26="",0,D26/E26)) -> 0 | M26: TP2 | P26: =O26*E$16 -> 0 | Q26: =IF(U26="","",P26) | R26: =N26*P26 -> 0 | S26: =IF(N26="",#N/A,S25+R26) -> #N/A
A27: Fractionnement | B27: 10 | C27: 3 | D27: =IF(C27<=B$27,B$28,"") -> 50 | F27: =IF(D27="",0,IF(E27="",0,D27/E27)) -> 0 | M27: TP3 | P27: =O27*E$16 -> 0 | Q27: =IF(U27="","",P27) | R27: =N27*P27 -> 0 | S27: =IF(N27="",#N/A,S26+R27) -> #N/A
A28: Montant IN | B28: =B26/B27 -> 50 | C28: 4 | D28: =IF(C28<=B$27,B$28,"") -> 50 | F28: =IF(D28="",0,IF(E28="",0,D28/E28)) -> 0 | M28: TP4 | P28: =O28*E$16 -> 0 | Q28: =IF(U28="","",P28) | R28: =N28*P28 -> 0 | S28: =IF(N28="",#N/A,S27+R28) -> #N/A
C29: 5 | D29: =IF(C29<=B$27,B$28,"") -> 50 | F29: =IF(D29="",0,IF(E29="",0,D29/E29)) -> 0 | M29: TP5 | P29: =O29*E$16 -> 0 | Q29: =IF(U29="","",P29) | R29: =N29*P29 -> 0 | S29: =IF(N29="",#N/A,S28+R29) -> #N/A
C30: 6 | D30: =IF(C30<=B$27,B$28,"") -> 50 | F30: =IF(D30="",0,IF(E30="",0,D30/E30)) -> 0 | M30: TP6 | P30: =O30*E$16 -> 0 | Q30: =IF(U30="","",P30) | R30: =N30*P30 -> 0 | S30: =IF(N30="",#N/A,S29+R30) -> #N/A
C31: 7 | D31: =IF(C31<=B$27,B$28,"") -> 50 | F31: =IF(D31="",0,IF(E31="",0,D31/E31)) -> 0 | M31: TP7 | P31: =O31*E$16 -> 0 | Q31: =IF(U31="","",P31) | R31: =N31*P31 -> 0 | S31: =IF(N31="",#N/A,S30+R31) -> #N/A
C32: 8 | D32: =IF(C32<=B$27,B$28,"") -> 50 | F32: =IF(D32="",0,IF(E32="",0,D32/E32)) -> 0 | M32: TP8 | P32: =O32*E$16 -> 0 | Q32: =IF(U32="","",P32) | R32: =N32*P32 -> 0 | S32: =IF(N32="",#N/A,S31+R32) -> #N/A
C33: 9 | D33: =IF(C33<=B$27,B$28,"") -> 50 | F33: =IF(D33="",0,IF(E33="",0,D33/E33)) -> 0 | M33: TP9 | P33: =O33*E$16 -> 0 | Q33: =IF(U33="","",P33) | R33: =N33*P33 -> 0 | S33: =IF(N33="",#N/A,S32+R33) -> #N/A
C34: 10 | D34: =IF(C34<=B$27,B$28,"") -> 50 | F34: =IF(D34="",0,IF(E34="",0,D34/E34)) -> 0 | M34: TP10 | P34: =O34*E$16 -> 0 | Q34: =IF(U34="","",P34) | R34: =N34*P34 -> 0 | S34: =IF(N34="",#N/A,S33+R34) -> #N/A
C35: 11 | D35: =IF(C35<=B$27,B$28,"") | F35: =IF(D35="",0,IF(E35="",0,D35/E35)) -> 0 | N35: Total % | O35: =SUM(O25:O34) -> 0 | Q35: =SUM(Q25:Q34) -> 0
C36: 12 | D36: =IF(C36<=B$27,B$28,"") | F36: =IF(D36="",0,IF(E36="",0,D36/E36)) -> 0
C37: 13 | D37: =IF(C37<=B$27,B$28,"") | F37: =IF(D37="",0,IF(E37="",0,D37/E37)) -> 0
C38: 14 | D38: =IF(C38<=B$27,B$28,"") | F38: =IF(D38="",0,IF(E38="",0,D38/E38)) -> 0
C39: 15 | D39: =IF(C39<=B$27,B$28,"") | F39: =IF(D39="",0,IF(E39="",0,D39/E39)) -> 0
C40: 16 | D40: =IF(C40<=B$27,B$28,"") | F40: =IF(D40="",0,IF(E40="",0,D40/E40)) -> 0
C41: 17 | D41: =IF(C41<=B$27,B$28,"") | F41: =IF(D41="",0,IF(E41="",0,D41/E41)) -> 0
C42: 18 | D42: =IF(C42<=B$27,B$28,"") | F42: =IF(D42="",0,IF(E42="",0,D42/E42)) -> 0
C43: 19 | D43: =IF(C43<=B$27,B$28,"") | F43: =IF(D43="",0,IF(E43="",0,D43/E43)) -> 0
C44: 20 | D44: =IF(C44<=B$27,B$28,"") | F44: =IF(D44="",0,IF(E44="",0,D44/E44)) -> 0
C45: 21 | D45: =IF(C45<=B$27,B$28,"") | F45: =IF(D45="",0,IF(E45="",0,D45/E45)) -> 0
C46: 22 | D46: =IF(C46<=B$27,B$28,"") | F46: =IF(D46="",0,IF(E46="",0,D46/E46)) -> 0
C47: 23 | D47: =IF(C47<=B$27,B$28,"") | F47: =IF(D47="",0,IF(E47="",0,D47/E47)) -> 0
... C49: 25 | D49: =IF(C49<=B$27,B$28,"") | F49: =IF(D49="",0,IF(E49="",0,D49/E49)) -> 0
A50: Achat unique | C50: 1 | F50: =IF(D50="",0,IF(E50="",0,D50/E50)) -> 0
A51: Dollar Cost Average (DCA) | C51: 2 | F51: =IF(D51="",0,IF(E51="",0,D51/E51)) -> 0
A52: Ordre Limite | C52: 3 | F52: =IF(D52="",0,IF(E52="",0,D52/E52)) -> 0
A53: Ordre Market | C53: 4 | F53: =IF(D53="",0,IF(E53="",0,D53/E53)) -> 0
C54: 5 | F54: =IF(D54="",0,IF(E54="",0,D54/E54)) -> 0
C55: 6 | F55: =IF(D55="",0,IF(E55="",0,D55/E55)) -> 0 | N55: TOTAL VENTE théorique | O55: =SUM(R25:R34) -> 0 | P55: =R55/O55 -> #DIV/0! | Q55: TOTAL VENTE Validée | R55: =SUMIF(U25:U34,"x",R25:R34) -> 0
C56: 7 | F56: =IF(D56="",0,IF(E56="",0,D56/E56)) -> 0
C57: 8 | F57: =IF(D57="",0,IF(E57="",0,D57/E57)) -> 0 | N57: Rendement théorique | O57: =(O55/F16)-1 -> #DIV/0! | Q57: Rendement en cours | R57: =(R55-F16)/F16 -> #DIV/0!
...

Sheet 7
B3: NOM de l'Actif
E15: ="Total Achat "&B4&"" -> Total Achat | F15: Total Achats ($) | H15: Résultat Net | J15: =R55-F16 -> 0 | P15: ="Total Vente "&B4&"" -> Total Vente | Q15: Total Ventes ($)
E16: =SUMIF(H25:H124,"x",F25:F124) -> 0 | F16: =SUMIF(H25:H124,"x",D25:D124) -> 0 | O16: =J15 -> 0 | P16: =Q35 -> 0 | Q16: =R55 -> 0
H17: ="Balance "&B4&"" -> Balance | J17: =E16-P16 -> 0
E18: Prix Moyen d'Achat | F18: =F16/E16 -> #DIV/0! | P18: Prix Moyen de Vente | Q18: =Q16/P16 -> #DIV/0!
N20: =J17 -> 0
A21: ACHATS | L21: VENTES
D24: Montant IN ($) | E24: ="Prix d'achat "&B4&"" -> Prix d'achat | F24: =B4&" acheté " -> acheté | G24: ORDRE posé | H24: ACHAT validé | I24: Date | N24: ="Prix de vente "&B4&"" -> Prix de vente | O24: % Distribution | P24: ="Nbre "&B4&" à vendre" -> Nbre à vendre | Q24: =B4&" vendu " -> vendu | R24: Montant OUT ($) | S24: Résultat Net | T24: ORDRE posé | U24: VENTE Validée | V24: Date
A25: Plan d'Achat | C25: 1 | D25: =IF(C25<=B$27,B$28,"") -> 50 | F25: =IF(D25="",0,IF(E25="",0,D25/E25)) -> 0 | M25: TP1 | P25: =O25*E$16 -> 0 | Q25: =IF(U25="","",P25) | R25: =N25*P25 -> 0 | S25: =IF(N25="",#N/A,R25-F$16) -> #N/A
A26: Capital Dispo | B26: 500 | C26: 2 | D26: =IF(C26<=B$27,B$28,"") -> 50 | F26: =IF(D26="",0,IF(E26="",0,D26/E26)) -> 0 | M26: TP2 | P26: =O26*E$16 -> 0 | Q26: =IF(U26="","",P26) | R26: =N26*P26 -> 0 | S26: =IF(N26="",#N/A,S25+R26) -> #N/A
A27: Fractionnement | B27: 10 | C27: 3 | D27: =IF(C27<=B$27,B$28,"") -> 50 | F27: =IF(D27="",0,IF(E27="",0,D27/E27)) -> 0 | M27: TP3 | P27: =O27*E$16 -> 0 | Q27: =IF(U27="","",P27) | R27: =N27*P27 -> 0 | S27: =IF(N27="",#N/A,S26+R27) -> #N/A
A28: Montant IN | B28: =B26/B27 -> 50 | C28: 4 | D28: =IF(C28<=B$27,B$28,"") -> 50 | F28: =IF(D28="",0,IF(E28="",0,D28/E28)) -> 0 | M28: TP4 | P28: =O28*E$16 -> 0 | Q28: =IF(U28="","",P28) | R28: =N28*P28 -> 0 | S28: =IF(N28="",#N/A,S27+R28) -> #N/A
C29: 5 | D29: =IF(C29<=B$27,B$28,"") -> 50 | F29: =IF(D29="",0,IF(E29="",0,D29/E29)) -> 0 | M29: TP5 | P29: =O29*E$16 -> 0 | Q29: =IF(U29="","",P29) | R29: =N29*P29 -> 0 | S29: =IF(N29="",#N/A,S28+R29) -> #N/A
C30: 6 | D30: =IF(C30<=B$27,B$28,"") -> 50 | F30: =IF(D30="",0,IF(E30="",0,D30/E30)) -> 0 | M30: TP6 | P30: =O30*E$16 -> 0 | Q30: =IF(U30="","",P30) | R30: =N30*P30 -> 0 | S30: =IF(N30="",#N/A,S29+R30) -> #N/A
C31: 7 | D31: =IF(C31<=B$27,B$28,"") -> 50 | F31: =IF(D31="",0,IF(E31="",0,D31/E31)) -> 0 | M31: TP7 | P31: =O31*E$16 -> 0 | Q31: =IF(U31="","",P31) | R31: =N31*P31 -> 0 | S31: =IF(N31="",#N/A,S30+R31) -> #N/A
C32: 8 | D32: =IF(C32<=B$27,B$28,"") -> 50 | F32: =IF(D32="",0,IF(E32="",0,D32/E32)) -> 0 | M32: TP8 | P32: =O32*E$16 -> 0 | Q32: =IF(U32="","",P32) | R32: =N32*P32 -> 0 | S32: =IF(N32="",#N/A,S31+R32) -> #N/A
C33: 9 | D33: =IF(C33<=B$27,B$28,"") -> 50 | F33: =IF(D33="",0,IF(E33="",0,D33/E33)) -> 0 | M33: TP9 | P33: =O33*E$16 -> 0 | Q33: =IF(U33="","",P33) | R33: =N33*P33 -> 0 | S33: =IF(N33="",#N/A,S32+R33) -> #N/A
C34: 10 | D34: =IF(C34<=B$27,B$28,"") -> 50 | F34: =IF(D34="",0,IF(E34="",0,D34/E34)) -> 0 | M34: TP10 | P34: =O34*E$16 -> 0 | Q34: =IF(U34="","",P34) | R34: =N34*P34 -> 0 | S34: =IF(N34="",#N/A,S33+R34) -> #N/A
C35: 11 | D35: =IF(C35<=B$27,B$28,"") | F35: =IF(D35="",0,IF(E35="",0,D35/E35)) -> 0 | N35: Total % | O35: =SUM(O25:O34) -> 0 | Q35: =SUM(Q25:Q34) -> 0
C36: 12 | D36: =IF(C36<=B$27,B$28,"") | F36: =IF(D36="",0,IF(E36="",0,D36/E36)) -> 0
C37: 13 | D37: =IF(C37<=B$27,B$28,"") | F37: =IF(D37="",0,IF(E37="",0,D37/E37)) -> 0
C38: 14 | D38: =IF(C38<=B$27,B$28,"") | F38: =IF(D38="",0,IF(E38="",0,D38/E38)) -> 0
C39: 15 | D39: =IF(C39<=B$27,B$28,"") | F39: =IF(D39="",0,IF(E39="",0,D39/E39)) -> 0
C40: 16 | D40: =IF(C40<=B$27,B$28,"") | F40: =IF(D40="",0,IF(E40="",0,D40/E40)) -> 0
C41: 17 | D41: =IF(C41<=B$27,B$28,"") | F41: =IF(D41="",0,IF(E41="",0,D41/E41)) -> 0
C42: 18 | D42: =IF(C42<=B$27,B$28,"") | F42: =IF(D42="",0,IF(E42="",0,D42/E42)) -> 0
C43: 19 | D43: =IF(C43<=B$27,B$28,"") | F43: =IF(D43="",0,IF(E43="",0,D43/E43)) -> 0
C44: 20 | D44: =IF(C44<=B$27,B$28,"") | F44: =IF(D44="",0,IF(E44="",0,D44/E44)) -> 0
C45: 21 | D45: =IF(C45<=B$27,B$28,"") | F45: =IF(D45="",0,IF(E45="",0,D45/E45)) -> 0
C46: 22 | D46: =IF(C46<=B$27,B$28,"") | F46: =IF(D46="",0,IF(E46="",0,D46/E46)) -> 0
C47: 23 | D47: =IF(C47<=B$27,B$28,"") | F47: =IF(D47="",0,IF(E47="",0,D47/E47)) -> 0
... C49: 25 | D49: =IF(C49<=B$27,B$28,"") | F49: =IF(D49="",0,IF(E49="",0,D49/E49)) -> 0
A50: Achat unique | C50: 1 | F50: =IF(D50="",0,IF(E50="",0,D50/E50)) -> 0
A51: Dollar Cost Average (DCA) | C51: 2 | F51: =IF(D51="",0,IF(E51="",0,D51/E51)) -> 0
A52: Ordre Limite | C52: 3 | F52: =IF(D52="",0,IF(E52="",0,D52/E52)) -> 0
A53: Ordre Market | C53: 4 | F53: =IF(D53="",0,IF(E53="",0,D53/E53)) -> 0
C54: 5 | F54: =IF(D54="",0,IF(E54="",0,D54/E54)) -> 0
C55: 6 | F55: =IF(D55="",0,IF(E55="",0,D55/E55)) -> 0 | N55: TOTAL VENTE théorique | O55: =SUM(R25:R34) -> 0 | P55: =R55/O55 -> #DIV/0! | Q55: TOTAL VENTE Validée | R55: =SUMIF(U25:U34,"x",R25:R34) -> 0
C56: 7 | F56: =IF(D56="",0,IF(E56="",0,D56/E56)) -> 0
C57: 8 | F57: =IF(D57="",0,IF(E57="",0,D57/E57)) -> 0 | N57: Rendement théorique | O57: =(O55/F16)-1 -> #DIV/0! | Q57: Rendement en cours | R57: =(R55-F16)/F16 -> #DIV/0!
...

Sheet 8
B3: NOM de l'Actif
E15: ="Total Achat "&B4&"" -> Total Achat | F15: Total Achats ($) | H15: Résultat Net | J15: =R55-F16 -> 0 | P15: ="Total Vente "&B4&"" -> Total Vente | Q15: Total Ventes ($)
E16: =SUMIF(H25:H124,"x",F25:F124) -> 0 | F16: =SUMIF(H25:H124,"x",D25:D124) -> 0 | O16: =J15 -> 0 | P16: =Q35 -> 0 | Q16: =R55 -> 0
H17: ="Balance "&B4&"" -> Balance | J17: =E16-P16 -> 0
E18: Prix Moyen d'Achat | F18: =F16/E16 -> #DIV/0! | P18: Prix Moyen de Vente | Q18: =Q16/P16 -> #DIV/0!
N20: =J17 -> 0
A21: ACHATS | L21: VENTES
D24: Montant IN ($) | E24: ="Prix d'achat "&B4&"" -> Prix d'achat | F24: =B4&" acheté " -> acheté | G24: ORDRE posé | H24: ACHAT validé | I24: Date | N24: ="Prix de vente "&B4&"" -> Prix de vente | O24: % Distribution | P24: ="Nbre "&B4&" à vendre" -> Nbre à vendre | Q24: =B4&" vendu " -> vendu | R24: Montant OUT ($) | S24: Résultat Net | T24: ORDRE posé | U24: VENTE Validée | V24: Date
A25: Plan d'Achat | C25: 1 | D25: =IF(C25<=B$27,B$28,"") -> 50 | F25: =IF(D25="",0,IF(E25="",0,D25/E25)) -> 0 | M25: TP1 | P25: =O25*E$16 -> 0 | Q25: =IF(U25="","",P25) | R25: =N25*P25 -> 0 | S25: =IF(N25="",#N/A,R25-F$16) -> #N/A
A26: Capital Dispo | B26: 500 | C26: 2 | D26: =IF(C26<=B$27,B$28,"") -> 50 | F26: =IF(D26="",0,IF(E26="",0,D26/E26)) -> 0 | M26: TP2 | P26: =O26*E$16 -> 0 | Q26: =IF(U26="","",P26) | R26: =N26*P26 -> 0 | S26: =IF(N26="",#N/A,S25+R26) -> #N/A
A27: Fractionnement | B27: 10 | C27: 3 | D27: =IF(C27<=B$27,B$28,"") -> 50 | F27: =IF(D27="",0,IF(E27="",0,D27/E27)) -> 0 | M27: TP3 | P27: =O27*E$16 -> 0 | Q27: =IF(U27="","",P27) | R27: =N27*P27 -> 0 | S27: =IF(N27="",#N/A,S26+R27) -> #N/A
A28: Montant IN | B28: =B26/B27 -> 50 | C28: 4 | D28: =IF(C28<=B$27,B$28,"") -> 50 | F28: =IF(D28="",0,IF(E28="",0,D28/E28)) -> 0 | M28: TP4 | P28: =O28*E$16 -> 0 | Q28: =IF(U28="","",P28) | R28: =N28*P28 -> 0 | S28: =IF(N28="",#N/A,S27+R28) -> #N/A
C29: 5 | D29: =IF(C29<=B$27,B$28,"") -> 50 | F29: =IF(D29="",0,IF(E29="",0,D29/E29)) -> 0 | M29: TP5 | P29: =O29*E$16 -> 0 | Q29: =IF(U29="","",P29) | R29: =N29*P29 -> 0 | S29: =IF(N29="",#N/A,S28+R29) -> #N/A
C30: 6 | D30: =IF(C30<=B$27,B$28,"") -> 50 | F30: =IF(D30="",0,IF(E30="",0,D30/E30)) -> 0 | M30: TP6 | P30: =O30*E$16 -> 0 | Q30: =IF(U30="","",P30) | R30: =N30*P30 -> 0 | S30: =IF(N30="",#N/A,S29+R30) -> #N/A
C31: 7 | D31: =IF(C31<=B$27,B$28,"") -> 50 | F31: =IF(D31="",0,IF(E31="",0,D31/E31)) -> 0 | M31: TP7 | P31: =O31*E$16 -> 0 | Q31: =IF(U31="","",P31) | R31: =N31*P31 -> 0 | S31: =IF(N31="",#N/A,S30+R31) -> #N/A
C32: 8 | D32: =IF(C32<=B$27,B$28,"") -> 50 | F32: =IF(D32="",0,IF(E32="",0,D32/E32)) -> 0 | M32: TP8 | P32: =O32*E$16 -> 0 | Q32: =IF(U32="","",P32) | R32: =N32*P32 -> 0 | S32: =IF(N32="",#N/A,S31+R32) -> #N/A
C33: 9 | D33: =IF(C33<=B$27,B$28,"") -> 50 | F33: =IF(D33="",0,IF(E33="",0,D33/E33)) -> 0 | M33: TP9 | P33: =O33*E$16 -> 0 | Q33: =IF(U33="","",P33) | R33: =N33*P33 -> 0 | S33: =IF(N33="",#N/A,S32+R33) -> #N/A
C34: 10 | D34: =IF(C34<=B$27,B$28,"") -> 50 | F34: =IF(D34="",0,IF(E34="",0,D34/E34)) -> 0 | M34: TP10 | P34: =O34*E$16 -> 0 | Q34: =IF(U34="","",P34) | R34: =N34*P34 -> 0 | S34: =IF(N34="",#N/A,S33+R34) -> #N/A
C35: 11 | D35: =IF(C35<=B$27,B$28,"") | F35: =IF(D35="",0,IF(E35="",0,D35/E35)) -> 0 | N35: Total % | O35: =SUM(O25:O34) -> 0 | Q35: =SUM(Q25:Q34) -> 0
C36: 12 | D36: =IF(C36<=B$27,B$28,"") | F36: =IF(D36="",0,IF(E36="",0,D36/E36)) -> 0
C37: 13 | D37: =IF(C37<=B$27,B$28,"") | F37: =IF(D37="",0,IF(E37="",0,D37/E37)) -> 0
C38: 14 | D38: =IF(C38<=B$27,B$28,"") | F38: =IF(D38="",0,IF(E38="",0,D38/E38)) -> 0
C39: 15 | D39: =IF(C39<=B$27,B$28,"") | F39: =IF(D39="",0,IF(E39="",0,D39/E39)) -> 0
C40: 16 | D40: =IF(C40<=B$27,B$28,"") | F40: =IF(D40="",0,IF(E40="",0,D40/E40)) -> 0
C41: 17 | D41: =IF(C41<=B$27,B$28,"") | F41: =IF(D41="",0,IF(E41="",0,D41/E41)) -> 0
C42: 18 | D42: =IF(C42<=B$27,B$28,"") | F42: =IF(D42="",0,IF(E42="",0,D42/E42)) -> 0
C43: 19 | D43: =IF(C43<=B$27,B$28,"") | F43: =IF(D43="",0,IF(E43="",0,D43/E43)) -> 0
C44: 20 | D44: =IF(C44<=B$27,B$28,"") | F44: =IF(D44="",0,IF(E44="",0,D44/E44)) -> 0
C45: 21 | D45: =IF(C45<=B$27,B$28,"") | F45: =IF(D45="",0,IF(E45="",0,D45/E45)) -> 0
C46: 22 | D46: =IF(C46<=B$27,B$28,"") | F46: =IF(D46="",0,IF(E46="",0,D46/E46)) -> 0
C47: 23 | D47: =IF(C47<=B$27,B$28,"") | F47: =IF(D47="",0,IF(E47="",0,D47/E47)) -> 0
... C49: 25 | D49: =IF(C49<=B$27,B$28,"") | F49: =IF(D49="",0,IF(E49="",0,D49/E49)) -> 0
A50: Achat unique | C50: 1 | F50: =IF(D50="",0,IF(E50="",0,D50/E50)) -> 0
A51: Dollar Cost Average (DCA) | C51: 2 | F51: =IF(D51="",0,IF(E51="",0,D51/E51)) -> 0
A52: Ordre Limite | C52: 3 | F52: =IF(D52="",0,IF(E52="",0,D52/E52)) -> 0
A53: Ordre Market | C53: 4 | F53: =IF(D53="",0,IF(E53="",0,D53/E53)) -> 0
C54: 5 | F54: =IF(D54="",0,IF(E54="",0,D54/E54)) -> 0
C55: 6 | F55: =IF(D55="",0,IF(E55="",0,D55/E55)) -> 0 | N55: TOTAL VENTE théorique | O55: =SUM(R25:R34) -> 0 | P55: =R55/O55 -> #DIV/0! | Q55: TOTAL VENTE Validée | R55: =SUMIF(U25:U34,"x",R25:R34) -> 0
C56: 7 | F56: =IF(D56="",0,IF(E56="",0,D56/E56)) -> 0
C57: 8 | F57: =IF(D57="",0,IF(E57="",0,D57/E57)) -> 0 | N57: Rendement théorique | O57: =(O55/F16)-1 -> #DIV/0! | Q57: Rendement en cours | R57: =(R55-F16)/F16 -> #DIV/0!
...

Sheet 9
B3: NOM de l'Actif
E15: ="Total Achat "&B4&"" -> Total Achat | F15: Total Achats ($) | H15: Résultat Net | J15: =R55-F16 -> 0 | P15: ="Total Vente "&B4&"" -> Total Vente | Q15: Total Ventes ($)
E16: =SUMIF(H25:H124,"x",F25:F124) -> 0 | F16: =SUMIF(H25:H124,"x",D25:D124) -> 0 | O16: =J15 -> 0 | P16: =Q35 -> 0 | Q16: =R55 -> 0
H17: ="Balance "&B4&"" -> Balance | J17: =E16-P16 -> 0
E18: Prix Moyen d'Achat | F18: =F16/E16 -> #DIV/0! | P18: Prix Moyen de Vente | Q18: =Q16/P16 -> #DIV/0!
N20: =J17 -> 0
A21: ACHATS | L21: VENTES
D24: Montant IN ($) | E24: ="Prix d'achat "&B4&"" -> Prix d'achat | F24: =B4&" acheté " -> acheté | G24: ORDRE posé | H24: ACHAT validé | I24: Date | N24: ="Prix de vente "&B4&"" -> Prix de vente | O24: % Distribution | P24: ="Nbre "&B4&" à vendre" -> Nbre à vendre | Q24: =B4&" vendu " -> vendu | R24: Montant OUT ($) | S24: Résultat Net | T24: ORDRE posé | U24: VENTE Validée | V24: Date
A25: Plan d'Achat | C25: 1 | D25: =IF(C25<=B$27,B$28,"") -> 50 | F25: =IF(D25="",0,IF(E25="",0,D25/E25)) -> 0 | M25: TP1 | P25: =O25*E$16 -> 0 | Q25: =IF(U25="","",P25) | R25: =N25*P25 -> 0 | S25: =IF(N25="",#N/A,R25-F$16) -> #N/A
A26: Capital Dispo | B26: 500 | C26: 2 | D26: =IF(C26<=B$27,B$28,"") -> 50 | F26: =IF(D26="",0,IF(E26="",0,D26/E26)) -> 0 | M26: TP2 | P26: =O26*E$16 -> 0 | Q26: =IF(U26="","",P26) | R26: =N26*P26 -> 0 | S26: =IF(N26="",#N/A,S25+R26) -> #N/A
A27: Fractionnement | B27: 10 | C27: 3 | D27: =IF(C27<=B$27,B$28,"") -> 50 | F27: =IF(D27="",0,IF(E27="",0,D27/E27)) -> 0 | M27: TP3 | P27: =O27*E$16 -> 0 | Q27: =IF(U27="","",P27) | R27: =N27*P27 -> 0 | S27: =IF(N27="",#N/A,S26+R27) -> #N/A
A28: Montant IN | B28: =B26/B27 -> 50 | C28: 4 | D28: =IF(C28<=B$27,B$28,"") -> 50 | F28: =IF(D28="",0,IF(E28="",0,D28/E28)) -> 0 | M28: TP4 | P28: =O28*E$16 -> 0 | Q28: =IF(U28="","",P28) | R28: =N28*P28 -> 0 | S28: =IF(N28="",#N/A,S27+R28) -> #N/A
C29: 5 | D29: =IF(C29<=B$27,B$28,"") -> 50 | F29: =IF(D29="",0,IF(E29="",0,D29/E29)) -> 0 | M29: TP5 | P29: =O29*E$16 -> 0 | Q29: =IF(U29="","",P29) | R29: =N29*P29 -> 0 | S29: =IF(N29="",#N/A,S28+R29) -> #N/A
C30: 6 | D30: =IF(C30<=B$27,B$28,"") -> 50 | F30: =IF(D30="",0,IF(E30="",0,D30/E30)) -> 0 | M30: TP6 | P30: =O30*E$16 -> 0 | Q30: =IF(U30="","",P30) | R30: =N30*P30 -> 0 | S30: =IF(N30="",#N/A,S29+R30) -> #N/A
C31: 7 | D31: =IF(C31<=B$27,B$28,"") -> 50 | F31: =IF(D31="",0,IF(E31="",0,D31/E31)) -> 0 | M31: TP7 | P31: =O31*E$16 -> 0 | Q31: =IF(U31="","",P31) | R31: =N31*P31 -> 0 | S31: =IF(N31="",#N/A,S30+R31) -> #N/A
C32: 8 | D32: =IF(C32<=B$27,B$28,"") -> 50 | F32: =IF(D32="",0,IF(E32="",0,D32/E32)) -> 0 | M32: TP8 | P32: =O32*E$16 -> 0 | Q32: =IF(U32="","",P32) | R32: =N32*P32 -> 0 | S32: =IF(N32="",#N/A,S31+R32) -> #N/A
C33: 9 | D33: =IF(C33<=B$27,B$28,"") -> 50 | F33: =IF(D33="",0,IF(E33="",0,D33/E33)) -> 0 | M33: TP9 | P33: =O33*E$16 -> 0 | Q33: =IF(U33="","",P33) | R33: =N33*P33 -> 0 | S33: =IF(N33="",#N/A,S32+R33) -> #N/A
C34: 10 | D34: =IF(C34<=B$27,B$28,"") -> 50 | F34: =IF(D34="",0,IF(E34="",0,D34/E34)) -> 0 | M34: TP10 | P34: =O34*E$16 -> 0 | Q34: =IF(U34="","",P34) | R34: =N34*P34 -> 0 | S34: =IF(N34="",#N/A,S33+R34) -> #N/A
C35: 11 | D35: =IF(C35<=B$27,B$28,"") | F35: =IF(D35="",0,IF(E35="",0,D35/E35)) -> 0 | N35: Total % | O35: =SUM(O25:O34) -> 0 | Q35: =SUM(Q25:Q34) -> 0
